Workbook

Sheet voptuna
A1: # | B1: PC | C1: Setpoint | D1: Rate | E1: Error | F1: Error^2 | G1: RMSE | H1: Goal Range (20%) | I1: Goal Range (10%) | K1: Sample | L1: Steady-state Time (s)
A2: 1 | B2: 1 | C2: 5000 | D2: 1712 | E2: =ABS(C2-D2) -> 3288 | F2: =POWER(E2,2) -> 10810944 | G2: =SQRT(SUM($F$2:F2)/A2) -> 3288 | H2: =IF(ABS(E2)/C2>0.2,0,1) -> 0 | I2: =IF(ABS(E2)/C2>0.1,0,1) -> 0 | K2: 1 | L2: 8
A3: 2 | B3: 4 | C3: 5000 | D3: 3319 | E3: =ABS(C3-D3) -> 1681 | F3: =POWER(E3,2) -> 2825761 | G3: =SQRT(SUM($F$2:F3)/A3) -> 2611.1975 | H3: =IF(ABS(E3)/C3>0.2,0,1) -> 0 | I3: =IF(ABS(E3)/C3>0.1,0,1) -> 0 | K3: 300 | L3: 8
A4: 3 | B4: 3 | C4: 5000 | D4: 2587 | E4: =ABS(C4-D4) -> 2413 | F4: =POWER(E4,2) -> 5822569 | G4: =SQRT(SUM($F$2:F4)/A4) -> 2546.846 | H4: =IF(ABS(E4)/C4>0.2,0,1) -> 0 | I4: =IF(ABS(E4)/C4>0.1,0,1) -> 0 | K4: 600 | L4: 7
A5: 4 | B5: 4 | C5: 5000 | D5: 3297 | E5: =ABS(C5-D5) -> 1703 | F5: =POWER(E5,2) -> 2900209 | G5: =SQRT(SUM($F$2:F5)/A5) -> 2364.2907 | H5: =IF(ABS(E5)/C5>0.2,0,1) -> 0 | I5: =IF(ABS(E5)/C5>0.1,0,1) -> 0 | K5: 900 | L5: 2
A6: 5 | B6: 4 | C6: 5000 | D6: 3088 | E6: =ABS(C6-D6) -> 1912 | F6: =POWER(E6,2) -> 3655744 | G6: =SQRT(SUM($F$2:F6)/A6) -> 2281.0185 | H6: =IF(ABS(E6)/C6>0.2,0,1) -> 0 | I6: =IF(ABS(E6)/C6>0.1,0,1) -> 0 | K6: 1200 | L6: 5
A7: 6 | B7: 5 | C7: 5000 | D7: 3828 | E7: =ABS(C7-D7) -> 1172 | F7: =POWER(E7,2) -> 1373584 | G7: =SQRT(SUM($F$2:F7)/A7) -> 2136.5397 | H7: =IF(ABS(E7)/C7>0.2,0,1) -> 0 | I7: =IF(ABS(E7)/C7>0.1,0,1) -> 0 | K7: 1500 | L7: 2
A8: 7 | B8: 5 | C8: 5000 | D8: 3411 | E8: =ABS(C8-D8) -> 1589 | F8: =POWER(E8,2) -> 2524921 | G8: =SQRT(SUM($F$2:F8)/A8) -> 2067.218 | H8: =IF(ABS(E8)/C8>0.2,0,1) -> 0 | I8: =IF(ABS(E8)/C8>0.1,0,1) -> 0 | K8: 1800 | L8: 6
A9: 8 | B9: 5 | C9: 5000 | D9: 4275 | E9: =ABS(C9-D9) -> 725 | F9: =POWER(E9,2) -> 525625 | G9: =SQRT(SUM($F$2:F9)/A9) -> 1950.6203 | H9: =IF(ABS(E9)/C9>0.2,0,1) -> 1 | I9: =IF(ABS(E9)/C9>0.1,0,1) -> 0 | K9: 2100 | L9: 4
A10: 9 | B10: 5 | C10: 5000 | D10: 4043 | E10: =ABS(C10-D10) -> 957 | F10: =POWER(E10,2) -> 915849 | G10: =SQRT(SUM($F$2:F10)/A10) -> 1866.524 | H10: =IF(ABS(E10)/C10>0.2,0,1) -> 1 | I10: =IF(ABS(E10)/C10>0.1,0,1) -> 0 | K10: 2400 | L10: 2
A11: 10 | B11: 5 | C11: 5000 | D11: 3867 | E11: =ABS(C11-D11) -> 1133 | F11: =POWER(E11,2) -> 1283689 | G11: =SQRT(SUM($F$2:F11)/A11) -> 1806.6238 | H11: =IF(ABS(E11)/C11>0.2,0,1) -> 0 | I11: =IF(ABS(E11)/C11>0.1,0,1) -> 0 | K11: Mean Time | L11: =AVERAGE(L2:L10) -> 4.8888889
A12: 11 | B12: 6 | C12: 5000 | D12: 4742 | E12: =ABS(C12-D12) -> 258 | F12: =POWER(E12,2) -> 66564 | G12: =SQRT(SUM($F$2:F12)/A12) -> 1724.3038 | H12: =IF(ABS(E12)/C12>0.2,0,1) -> 1 | I12: =IF(ABS(E12)/C12>0.1,0,1) -> 1
A13: 12 | B13: 5 | C13: 5000 | D13: 4102 | E13: =ABS(C13-D13) -> 898 | F13: =POWER(E13,2) -> 806404 | G13: =SQRT(SUM($F$2:F13)/A13) -> 1671.1239 | H13: =IF(ABS(E13)/C13>0.2,0,1) -> 1 | I13: =IF(ABS(E13)/C13>0.1,0,1) -> 0
A14: 13 | B14: 6 | C14: 5000 | D14: 3983 | E14: =ABS(C14-D14) -> 1017 | F14: =POWER(E14,2) -> 1034289 | G14: =SQRT(SUM($F$2:F14)/A14) -> 1630.1522 | H14: =IF(ABS(E14)/C14>0.2,0,1) -> 0 | I14: =IF(ABS(E14)/C14>0.1,0,1) -> 0
A15: 14 | B15: 6 | C15: 5000 | D15: 5155 | E15: =ABS(C15-D15) -> 155 | F15: =POWER(E15,2) -> 24025 | G15: =SQRT(SUM($F$2:F15)/A15) -> 1571.4001 | H15: =IF(ABS(E15)/C15>0.2,0,1) -> 1 | I15: =IF(ABS(E15)/C15>0.1,0,1) -> 1
A16: 15 | B16: 5 | C16: 5000 | D16: 3681 | E16: =ABS(C16-D16) -> 1319 | F16: =POWER(E16,2) -> 1739761 | G16: =SQRT(SUM($F$2:F16)/A16) -> 1555.8479 | H16: =IF(ABS(E16)/C16>0.2,0,1) -> 0 | I16: =IF(ABS(E16)/C16>0.1,0,1) -> 0
A17: 16 | B17: 7 | C17: 5000 | D17: 5285 | E17: =ABS(C17-D17) -> 285 | F17: =POWER(E17,2) -> 81225 | G17: =SQRT(SUM($F$2:F17)/A17) -> 1508.1272 | H17: =IF(ABS(E17)/C17>0.2,0,1) -> 1 | I17: =IF(ABS(E17)/C17>0.1,0,1) -> 1
A18: 17 | B18: 5 | C18: 5000 | D18: 4086 | E18: =ABS(C18-D18) -> 914 | F18: =POWER(E18,2) -> 835396 | G18: =SQRT(SUM($F$2:F18)/A18) -> 1479.7965 | H18: =IF(ABS(E18)/C18>0.2,0,1) -> 1 | I18: =IF(ABS(E18)/C18>0.1,0,1) -> 0
A19: 18 | B19: 7 | C19: 5000 | D19: 5673 | E19: =ABS(C19-D19) -> 673 | F19: =POWER(E19,2) -> 452929 | G19: =SQRT(SUM($F$2:F19)/A19) -> 1446.8258 | H19: =IF(ABS(E19)/C19>0.2,0,1) -> 1 | I19: =IF(ABS(E19)/C19>0.1,0,1) -> 0
A20: 19 | B20: 5 | C20: 5000 | D20: 3606 | E20: =ABS(C20-D20) -> 1394 | F20: =POWER(E20,2) -> 1943236 | G20: =SQRT(SUM($F$2:F20)/A20) -> 1444.0937 | H20: =IF(ABS(E20)/C20>0.2,0,1) -> 0 | I20: =IF(ABS(E20)/C20>0.1,0,1) -> 0
A21: 20 | B21: 7 | C21: 5000 | D21: 4654 | E21: =ABS(C21-D21) -> 346 | F21: =POWER(E21,2) -> 119716 | G21: =SQRT(SUM($F$2:F21)/A21) -> 1409.6531 | H21: =IF(ABS(E21)/C21>0.2,0,1) -> 1 | I21: =IF(ABS(E21)/C21>0.1,0,1) -> 1
A22: 21 | B22: 6 | C22: 5000 | D22: 4338 | E22: =ABS(C22-D22) -> 662 | F22: =POWER(E22,2) -> 438244 | G22: =SQRT(SUM($F$2:F22)/A22) -> 1383.2447 | H22: =IF(ABS(E22)/C22>0.2,0,1) -> 1 | I22: =IF(ABS(E22)/C22>0.1,0,1) -> 0
A23: 22 | B23: 7 | C23: 5000 | D23: 5080 | E23: =ABS(C23-D23) -> 80 | F23: =POWER(E23,2) -> 6400 | G23: =SQRT(SUM($F$2:F23)/A23) -> 1351.5493 | H23: =IF(ABS(E23)/C23>0.2,0,1) -> 1 | I23: =IF(ABS(E23)/C23>0.1,0,1) -> 1
... A2501: 2500 | B2501: 8 | C2501: 5000 | D2501: 4945 | E2501: =ABS(C2501-D2501) -> 55 | F2501: =POWER(E2501,2) -> 3025 | G2501: =SQRT(SUM($F$2:F2501)/A2501) -> 1044.0186 | H2501: =IF(ABS(E2501)/C2501>0.2,0,1) -> 1 | I2501: =IF(ABS(E2501)/C2501>0.1,0,1) -> 1

Sheet vrl
A1: # | B1: PC | C1: Setpoint | D1: Rate | E1: Error | F1: Error^2 | G1: RMSE | H1: Goal Range (20%) | I1: Goal Range (10%) | K1: Sample | L1: Steady-state Time (s)
A2: 1 | B2: 1 | C2: 5000 | D2: 1385 | E2: =ABS(C2-D2) -> 3615 | F2: =POWER(E2,2) -> 13068225 | G2: =SQRT(SUM($F$2:F2)/A2) -> 3615 | H2: =IF(ABS(E2)/C2>0.2,0,1) -> 0 | I2: =IF(ABS(E2)/C2>0.1,0,1) -> 0 | K2: 1 | L2: 2
A3: 2 | B3: 5 | C3: 5000 | D3: 4089 | E3: =ABS(C3-D3) -> 911 | F3: =POWER(E3,2) -> 829921 | G3: =SQRT(SUM($F$2:F3)/A3) -> 2636.1094 | H3: =IF(ABS(E3)/C3>0.2,0,1) -> 1 | I3: =IF(ABS(E3)/C3>0.1,0,1) -> 0 | K3: 300 | L3: 9
A4: 3 | B4: 2 | C4: 5000 | D4: 1889 | E4: =ABS(C4-D4) -> 3111 | F4: =POWER(E4,2) -> 9678321 | G4: =SQRT(SUM($F$2:F4)/A4) -> 2803.3591 | H4: =IF(ABS(E4)/C4>0.2,0,1) -> 0 | I4: =IF(ABS(E4)/C4>0.1,0,1) -> 0 | K4: 600 | L4: 8
A5: 4 | B5: 5 | C5: 5000 | D5: 4460 | E5: =ABS(C5-D5) -> 540 | F5: =POWER(E5,2) -> 291600 | G5: =SQRT(SUM($F$2:F5)/A5) -> 2442.7478 | H5: =IF(ABS(E5)/C5>0.2,0,1) -> 1 | I5: =IF(ABS(E5)/C5>0.1,0,1) -> 0 | K5: 900 | L5: 4
A6: 5 | B6: 3 | C6: 5000 | D6: 2550 | E6: =ABS(C6-D6) -> 2450 | F6: =POWER(E6,2) -> 6002500 | G6: =SQRT(SUM($F$2:F6)/A6) -> 2444.2 | H6: =IF(ABS(E6)/C6>0.2,0,1) -> 0 | I6: =IF(ABS(E6)/C6>0.1,0,1) -> 0 | K6: 1200 | L6: 10
A7: 6 | B7: 5 | C7: 5000 | D7: 4049 | E7: =ABS(C7-D7) -> 951 | F7: =POWER(E7,2) -> 904401 | G7: =SQRT(SUM($F$2:F7)/A7) -> 2264.7652 | H7: =IF(ABS(E7)/C7>0.2,0,1) -> 1 | I7: =IF(ABS(E7)/C7>0.1,0,1) -> 0 | K7: 1500 | L7: 2
A8: 7 | B8: 4 | C8: 5000 | D8: 3177 | E8: =ABS(C8-D8) -> 1823 | F8: =POWER(E8,2) -> 3323329 | G8: =SQRT(SUM($F$2:F8)/A8) -> 2207.0762 | H8: =IF(ABS(E8)/C8>0.2,0,1) -> 0 | I8: =IF(ABS(E8)/C8>0.1,0,1) -> 0 | K8: 1800 | L8: 15
A9: 8 | B9: 6 | C9: 5000 | D9: 4501 | E9: =ABS(C9-D9) -> 499 | F9: =POWER(E9,2) -> 249001 | G9: =SQRT(SUM($F$2:F9)/A9) -> 2072.0551 | H9: =IF(ABS(E9)/C9>0.2,0,1) -> 1 | I9: =IF(ABS(E9)/C9>0.1,0,1) -> 1 | K9: 2100 | L9: 7
A10: 9 | B10: 4 | C10: 5000 | D10: 3322 | E10: =ABS(C10-D10) -> 1678 | F10: =POWER(E10,2) -> 2815684 | G10: =SQRT(SUM($F$2:F10)/A10) -> 2032.0483 | H10: =IF(ABS(E10)/C10>0.2,0,1) -> 0 | I10: =IF(ABS(E10)/C10>0.1,0,1) -> 0 | K10: 2400 | L10: 9
A11: 10 | B11: 6 | C11: 5000 | D11: 4883 | E11: =ABS(C11-D11) -> 117 | F11: =POWER(E11,2) -> 13689 | G11: =SQRT(SUM($F$2:F11)/A11) -> 1928.1253 | H11: =IF(ABS(E11)/C11>0.2,0,1) -> 1 | I11: =IF(ABS(E11)/C11>0.1,0,1) -> 1 | K11: Mean Time | L11: =AVERAGE(L2:L10) -> 7.3333333
A12: 11 | B12: 5 | C12: 5000 | D12: 4333 | E12: =ABS(C12-D12) -> 667 | F12: =POWER(E12,2) -> 444889 | G12: =SQRT(SUM($F$2:F12)/A12) -> 1849.3625 | H12: =IF(ABS(E12)/C12>0.2,0,1) -> 1 | I12: =IF(ABS(E12)/C12>0.1,0,1) -> 0
A13: 12 | B13: 5 | C13: 5000 | D13: 4118 | E13: =ABS(C13-D13) -> 882 | F13: =POWER(E13,2) -> 777924 | G13: =SQRT(SUM($F$2:F13)/A13) -> 1788.8424 | H13: =IF(ABS(E13)/C13>0.2,0,1) -> 1 | I13: =IF(ABS(E13)/C13>0.1,0,1) -> 0
A14: 13 | B14: 6 | C14: 5000 | D14: 4729 | E14: =ABS(C14-D14) -> 271 | F14: =POWER(E14,2) -> 73441 | G14: =SQRT(SUM($F$2:F14)/A14) -> 1720.3069 | H14: =IF(ABS(E14)/C14>0.2,0,1) -> 1 | I14: =IF(ABS(E14)/C14>0.1,0,1) -> 1
A15: 14 | B15: 5 | C15: 5000 | D15: 4364 | E15: =ABS(C15-D15) -> 636 | F15: =POWER(E15,2) -> 404496 | G15: =SQRT(SUM($F$2:F15)/A15) -> 1666.4209 | H15: =IF(ABS(E15)/C15>0.2,0,1) -> 1 | I15: =IF(ABS(E15)/C15>0.1,0,1) -> 0
A16: 15 | B16: 6 | C16: 5000 | D16: 4356 | E16: =ABS(C16-D16) -> 644 | F16: =POWER(E16,2) -> 414736 | G16: =SQRT(SUM($F$2:F16)/A16) -> 1618.4799 | H16: =IF(ABS(E16)/C16>0.2,0,1) -> 1 | I16: =IF(ABS(E16)/C16>0.1,0,1) -> 0
A17: 16 | B17: 6 | C17: 5000 | D17: 4592 | E17: =ABS(C17-D17) -> 408 | F17: =POWER(E17,2) -> 166464 | G17: =SQRT(SUM($F$2:F17)/A17) -> 1570.4024 | H17: =IF(ABS(E17)/C17>0.2,0,1) -> 1 | I17: =IF(ABS(E17)/C17>0.1,0,1) -> 1
A18: 17 | B18: 6 | C18: 5000 | D18: 5177 | E18: =ABS(C18-D18) -> 177 | F18: =POWER(E18,2) -> 31329 | G18: =SQRT(SUM($F$2:F18)/A18) -> 1524.1188 | H18: =IF(ABS(E18)/C18>0.2,0,1) -> 1 | I18: =IF(ABS(E18)/C18>0.1,0,1) -> 1
A19: 18 | B19: 5 | C19: 5000 | D19: 4045 | E19: =ABS(C19-D19) -> 955 | F19: =POWER(E19,2) -> 912025 | G19: =SQRT(SUM($F$2:F19)/A19) -> 1498.1836 | H19: =IF(ABS(E19)/C19>0.2,0,1) -> 1 | I19: =IF(ABS(E19)/C19>0.1,0,1) -> 0
A20: 19 | B20: 7 | C20: 5000 | D20: 5504 | E20: =ABS(C20-D20) -> 504 | F20: =POWER(E20,2) -> 254016 | G20: =SQRT(SUM($F$2:F20)/A20) -> 1462.8018 | H20: =IF(ABS(E20)/C20>0.2,0,1) -> 1 | I20: =IF(ABS(E20)/C20>0.1,0,1) -> 0
A21: 20 | B21: 5 | C21: 5000 | D21: 4121 | E21: =ABS(C21-D21) -> 879 | F21: =POWER(E21,2) -> 772641 | G21: =SQRT(SUM($F$2:F21)/A21) -> 1439.2469 | H21: =IF(ABS(E21)/C21>0.2,0,1) -> 1 | I21: =IF(ABS(E21)/C21>0.1,0,1) -> 0
A22: 21 | B22: 7 | C22: 5000 | D22: 4228 | E22: =ABS(C22-D22) -> 772 | F22: =POWER(E22,2) -> 595984 | G22: =SQRT(SUM($F$2:F22)/A22) -> 1414.6279 | H22: =IF(ABS(E22)/C22>0.2,0,1) -> 1 | I22: =IF(ABS(E22)/C22>0.1,0,1) -> 0
A23: 22 | B23: 7 | C23: 5000 | D23: 2438 | E23: =ABS(C23-D23) -> 2562 | F23: =POWER(E23,2) -> 6563844 | G23: =SQRT(SUM($F$2:F23)/A23) -> 1486.1246 | H23: =IF(ABS(E23)/C23>0.2,0,1) -> 0 | I23: =IF(ABS(E23)/C23>0.1,0,1) -> 0
... A2501: 2500 | B2501: 9 | C2501: 5000 | D2501: 5696 | E2501: =ABS(C2501-D2501) -> 696 | F2501: =POWER(E2501,2) -> 484416 | G2501: =SQRT(SUM($F$2:F2501)/A2501) -> 995.46239 | H2501: =IF(ABS(E2501)/C2501>0.2,0,1) -> 1 | I2501: =IF(ABS(E2501)/C2501>0.1,0,1) -> 0

Sheet vspsa
A1: # | B1: PC | C1: Setpoint | D1: Rate | E1: Error | F1: Error^2 | G1: RMSE | H1: Goal Range (20%) | I1: Goal Range (10%) | K1: Sample | L1: Steady-state Time (s)
A2: 1 | B2: 1 | C2: 5000 | D2: 1866 | E2: =ABS(C2-D2) -> 3134 | F2: =POWER(E2,2) -> 9821956 | G2: =SQRT(SUM($F$2:F2)/A2) -> 3134 | H2: =IF(ABS(E2)/C2>0.2,0,1) -> 0 | I2: =IF(ABS(E2)/C2>0.1,0,1) -> 0 | K2: 1 | L2: 4
A3: 2 | B3: 4 | C3: 5000 | D3: 3106 | E3: =ABS(C3-D3) -> 1894 | F3: =POWER(E3,2) -> 3587236 | G3: =SQRT(SUM($F$2:F3)/A3) -> 2589.3235 | H3: =IF(ABS(E3)/C3>0.2,0,1) -> 0 | I3: =IF(ABS(E3)/C3>0.1,0,1) -> 0 | K3: 300 | L3: 2
A4: 3 | B4: 3 | C4: 5000 | D4: 2493 | E4: =ABS(C4-D4) -> 2507 | F4: =POWER(E4,2) -> 6285049 | G4: =SQRT(SUM($F$2:F4)/A4) -> 2562.1762 | H4: =IF(ABS(E4)/C4>0.2,0,1) -> 0 | I4: =IF(ABS(E4)/C4>0.1,0,1) -> 0 | K4: 600 | L4: 2
A5: 4 | B5: 5 | C5: 5000 | D5: 4037 | E5: =ABS(C5-D5) -> 963 | F5: =POWER(E5,2) -> 927369 | G5: =SQRT(SUM($F$2:F5)/A5) -> 2270.5511 | H5: =IF(ABS(E5)/C5>0.2,0,1) -> 1 | I5: =IF(ABS(E5)/C5>0.1,0,1) -> 0 | K5: 900 | L5: 4
A6: 5 | B6: 3 | C6: 5000 | D6: 2416 | E6: =ABS(C6-D6) -> 2584 | F6: =POWER(E6,2) -> 6677056 | G6: =SQRT(SUM($F$2:F6)/A6) -> 2336.6072 | H6: =IF(ABS(E6)/C6>0.2,0,1) -> 0 | I6: =IF(ABS(E6)/C6>0.1,0,1) -> 0 | K6: 1200 | L6: 7
A7: 6 | B7: 6 | C7: 5000 | D7: 5182 | E7: =ABS(C7-D7) -> 182 | F7: =POWER(E7,2) -> 33124 | G7: =SQRT(SUM($F$2:F7)/A7) -> 2134.3145 | H7: =IF(ABS(E7)/C7>0.2,0,1) -> 1 | I7: =IF(ABS(E7)/C7>0.1,0,1) -> 1 | K7: 1500 | L7: 8
A8: 7 | B8: 3 | C8: 5000 | D8: 2790 | E8: =ABS(C8-D8) -> 2210 | F8: =POWER(E8,2) -> 4884100 | G8: =SQRT(SUM($F$2:F8)/A8) -> 2145.2902 | H8: =IF(ABS(E8)/C8>0.2,0,1) -> 0 | I8: =IF(ABS(E8)/C8>0.1,0,1) -> 0 | K8: 1800 | L8: 4
A9: 8 | B9: 6 | C9: 5000 | D9: 5104 | E9: =ABS(C9-D9) -> 104 | F9: =POWER(E9,2) -> 10816 | G9: =SQRT(SUM($F$2:F9)/A9) -> 2007.0721 | H9: =IF(ABS(E9)/C9>0.2,0,1) -> 1 | I9: =IF(ABS(E9)/C9>0.1,0,1) -> 1 | K9: 2100 | L9: 4
A10: 9 | B10: 4 | C10: 5000 | D10: 3555 | E10: =ABS(C10-D10) -> 1445 | F10: =POWER(E10,2) -> 2088025 | G10: =SQRT(SUM($F$2:F10)/A10) -> 1952.6259 | H10: =IF(ABS(E10)/C10>0.2,0,1) -> 0 | I10: =IF(ABS(E10)/C10>0.1,0,1) -> 0 | K10: 2400 | L10: 10
A11: 10 | B11: 5 | C11: 5000 | D11: 4143 | E11: =ABS(C11-D11) -> 857 | F11: =POWER(E11,2) -> 734449 | G11: =SQRT(SUM($F$2:F11)/A11) -> 1872.1426 | H11: =IF(ABS(E11)/C11>0.2,0,1) -> 1 | I11: =IF(ABS(E11)/C11>0.1,0,1) -> 0 | K11: Mean Time | L11: =AVERAGE(L2:L10) -> 5
A12: 11 | B12: 5 | C12: 5000 | D12: 4254 | E12: =ABS(C12-D12) -> 746 | F12: =POWER(E12,2) -> 556516 | G12: =SQRT(SUM($F$2:F12)/A12) -> 1799.1335 | H12: =IF(ABS(E12)/C12>0.2,0,1) -> 1 | I12: =IF(ABS(E12)/C12>0.1,0,1) -> 0
A13: 12 | B13: 5 | C13: 5000 | D13: 4084 | E13: =ABS(C13-D13) -> 916 | F13: =POWER(E13,2) -> 839056 | G13: =SQRT(SUM($F$2:F13)/A13) -> 1742.717 | H13: =IF(ABS(E13)/C13>0.2,0,1) -> 1 | I13: =IF(ABS(E13)/C13>0.1,0,1) -> 0
A14: 13 | B14: 6 | C14: 5000 | D14: 4731 | E14: =ABS(C14-D14) -> 269 | F14: =POWER(E14,2) -> 72361 | G14: =SQRT(SUM($F$2:F14)/A14) -> 1676.0098 | H14: =IF(ABS(E14)/C14>0.2,0,1) -> 1 | I14: =IF(ABS(E14)/C14>0.1,0,1) -> 1
A15: 14 | B15: 5 | C15: 5000 | D15: 3811 | E15: =ABS(C15-D15) -> 1189 | F15: =POWER(E15,2) -> 1413721 | G15: =SQRT(SUM($F$2:F15)/A15) -> 1646.0089 | H15: =IF(ABS(E15)/C15>0.2,0,1) -> 0 | I15: =IF(ABS(E15)/C15>0.1,0,1) -> 0
A16: 15 | B16: 6 | C16: 5000 | D16: 4997 | E16: =ABS(C16-D16) -> 3 | F16: =POWER(E16,2) -> 9 | G16: =SQRT(SUM($F$2:F16)/A16) -> 1590.1959 | H16: =IF(ABS(E16)/C16>0.2,0,1) -> 1 | I16: =IF(ABS(E16)/C16>0.1,0,1) -> 1
A17: 16 | B17: 5 | C17: 5000 | D17: 4030 | E17: =ABS(C17-D17) -> 970 | F17: =POWER(E17,2) -> 940900 | G17: =SQRT(SUM($F$2:F17)/A17) -> 1558.6802 | H17: =IF(ABS(E17)/C17>0.2,0,1) -> 1 | I17: =IF(ABS(E17)/C17>0.1,0,1) -> 0
A18: 17 | B18: 6 | C18: 5000 | D18: 4330 | E18: =ABS(C18-D18) -> 670 | F18: =POWER(E18,2) -> 448900 | G18: =SQRT(SUM($F$2:F18)/A18) -> 1520.8481 | H18: =IF(ABS(E18)/C18>0.2,0,1) -> 1 | I18: =IF(ABS(E18)/C18>0.1,0,1) -> 0
A19: 18 | B19: 6 | C19: 5000 | D19: 4965 | E19: =ABS(C19-D19) -> 35 | F19: =POWER(E19,2) -> 1225 | G19: =SQRT(SUM($F$2:F19)/A19) -> 1478.0217 | H19: =IF(ABS(E19)/C19>0.2,0,1) -> 1 | I19: =IF(ABS(E19)/C19>0.1,0,1) -> 1
A20: 19 | B20: 6 | C20: 5000 | D20: 4725 | E20: =ABS(C20-D20) -> 275 | F20: =POWER(E20,2) -> 75625 | G20: =SQRT(SUM($F$2:F20)/A20) -> 1439.9834 | H20: =IF(ABS(E20)/C20>0.2,0,1) -> 1 | I20: =IF(ABS(E20)/C20>0.1,0,1) -> 1
A21: 20 | B21: 6 | C21: 5000 | D21: 4808 | E21: =ABS(C21-D21) -> 192 | F21: =POWER(E21,2) -> 36864 | G21: =SQRT(SUM($F$2:F21)/A21) -> 1404.1787 | H21: =IF(ABS(E21)/C21>0.2,0,1) -> 1 | I21: =IF(ABS(E21)/C21>0.1,0,1) -> 1
A22: 21 | B22: 6 | C22: 5000 | D22: 4231 | E22: =ABS(C22-D22) -> 769 | F22: =POWER(E22,2) -> 591361 | G22: =SQRT(SUM($F$2:F22)/A22) -> 1380.5747 | H22: =IF(ABS(E22)/C22>0.2,0,1) -> 1 | I22: =IF(ABS(E22)/C22>0.1,0,1) -> 0
A23: 22 | B23: 7 | C23: 5000 | D23: 5060 | E23: =ABS(C23-D23) -> 60 | F23: =POWER(E23,2) -> 3600 | G23: =SQRT(SUM($F$2:F23)/A23) -> 1348.8938 | H23: =IF(ABS(E23)/C23>0.2,0,1) -> 1 | I23: =IF(ABS(E23)/C23>0.1,0,1) -> 1
... A2501: 2500 | B2501: 6 | C2501: 5000 | D2501: 4898 | E2501: =ABS(C2501-D2501) -> 102 | F2501: =POWER(E2501,2) -> 10404 | G2501: =SQRT(SUM($F$2:F2501)/A2501) -> 1130.0448 | H2501: =IF(ABS(E2501)/C2501>0.2,0,1) -> 1 | I2501: =IF(ABS(E2501)/C2501>0.1,0,1) -> 1

Sheet vbayes
A1: # | B1: PC | C1: Setpoint | D1: Rate | E1: Error | F1: Error^2 | G1: RMSE | H1: Goal Range (20%) | I1: Goal Range (10%) | K1: Sample | L1: Steady-state Time (s)
A2: 1 | B2: 1 | C2: 5000 | D2: 1881 | E2: =ABS(C2-D2) -> 3119 | F2: =POWER(E2,2) -> 9728161 | G2: =SQRT(SUM($F$2:F2)/A2) -> 3119 | H2: =IF(ABS(E2)/C2>0.2,0,1) -> 0 | I2: =IF(ABS(E2)/C2>0.1,0,1) -> 0 | K2: 1 | L2: 11
A3: 2 | B3: 4 | C3: 5000 | D3: 3650 | E3: =ABS(C3-D3) -> 1350 | F3: =POWER(E3,2) -> 1822500 | G3: =SQRT(SUM($F$2:F3)/A3) -> 2403.1917 | H3: =IF(ABS(E3)/C3>0.2,0,1) -> 0 | I3: =IF(ABS(E3)/C3>0.1,0,1) -> 0 | K3: 300 | L3: 10
A4: 3 | B4: 3 | C4: 5000 | D4: 2607 | E4: =ABS(C4-D4) -> 2393 | F4: =POWER(E4,2) -> 5726449 | G4: =SQRT(SUM($F$2:F4)/A4) -> 2399.7993 | H4: =IF(ABS(E4)/C4>0.2,0,1) -> 0 | I4: =IF(ABS(E4)/C4>0.1,0,1) -> 0 | K4: 600 | L4: 8
A5: 4 | B5: 4 | C5: 5000 | D5: 3853 | E5: =ABS(C5-D5) -> 1147 | F5: =POWER(E5,2) -> 1315609 | G5: =SQRT(SUM($F$2:F5)/A5) -> 2155.9638 | H5: =IF(ABS(E5)/C5>0.2,0,1) -> 0 | I5: =IF(ABS(E5)/C5>0.1,0,1) -> 0 | K5: 900 | L5: 2
A6: 5 | B6: 3 | C6: 5000 | D6: 2963 | E6: =ABS(C6-D6) -> 2037 | F6: =POWER(E6,2) -> 4149369 | G6: =SQRT(SUM($F$2:F6)/A6) -> 2132.7019 | H6: =IF(ABS(E6)/C6>0.2,0,1) -> 0 | I6: =IF(ABS(E6)/C6>0.1,0,1) -> 0 | K6: 1200 | L6: 9
A7: 6 | B7: 5 | C7: 5000 | D7: 4174 | E7: =ABS(C7-D7) -> 826 | F7: =POWER(E7,2) -> 682276 | G7: =SQRT(SUM($F$2:F7)/A7) -> 1975.8696 | H7: =IF(ABS(E7)/C7>0.2,0,1) -> 1 | I7: =IF(ABS(E7)/C7>0.1,0,1) -> 0 | K7: 1500 | L7: 10
A8: 7 | B8: 4 | C8: 5000 | D8: 3165 | E8: =ABS(C8-D8) -> 1835 | F8: =POWER(E8,2) -> 3367225 | G8: =SQRT(SUM($F$2:F8)/A8) -> 1956.3665 | H8: =IF(ABS(E8)/C8>0.2,0,1) -> 0 | I8: =IF(ABS(E8)/C8>0.1,0,1) -> 0 | K8: 1800 | L8: 13
A9: 8 | B9: 5 | C9: 5000 | D9: 4786 | E9: =ABS(C9-D9) -> 214 | F9: =POWER(E9,2) -> 45796 | G9: =SQRT(SUM($F$2:F9)/A9) -> 1831.5767 | H9: =IF(ABS(E9)/C9>0.2,0,1) -> 1 | I9: =IF(ABS(E9)/C9>0.1,0,1) -> 1 | K9: 2100 | L9: 14
A10: 9 | B10: 4 | C10: 5000 | D10: 3454 | E10: =ABS(C10-D10) -> 1546 | F10: =POWER(E10,2) -> 2390116 | G10: =SQRT(SUM($F$2:F10)/A10) -> 1802.0822 | H10: =IF(ABS(E10)/C10>0.2,0,1) -> 0 | I10: =IF(ABS(E10)/C10>0.1,0,1) -> 0 | K10: 2400 | L10: 16
A11: 10 | B11: 6 | C11: 5000 | D11: 5181 | E11: =ABS(C11-D11) -> 181 | F11: =POWER(E11,2) -> 32761 | G11: =SQRT(SUM($F$2:F11)/A11) -> 1710.5631 | H11: =IF(ABS(E11)/C11>0.2,0,1) -> 1 | I11: =IF(ABS(E11)/C11>0.1,0,1) -> 1 | K11: Mean Time | L11: =AVERAGE(L2:L10) -> 10.333333
A12: 11 | B12: 4 | C12: 5000 | D12: 3587 | E12: =ABS(C12-D12) -> 1413 | F12: =POWER(E12,2) -> 1996569 | G12: =SQRT(SUM($F$2:F12)/A12) -> 1685.6839 | H12: =IF(ABS(E12)/C12>0.2,0,1) -> 0 | I12: =IF(ABS(E12)/C12>0.1,0,1) -> 0
A13: 12 | B13: 6 | C13: 5000 | D13: 5469 | E13: =ABS(C13-D13) -> 469 | F13: =POWER(E13,2) -> 219961 | G13: =SQRT(SUM($F$2:F13)/A13) -> 1619.5882 | H13: =IF(ABS(E13)/C13>0.2,0,1) -> 1 | I13: =IF(ABS(E13)/C13>0.1,0,1) -> 1
A14: 13 | B14: 4 | C14: 5000 | D14: 3205 | E14: =ABS(C14-D14) -> 1795 | F14: =POWER(E14,2) -> 3222025 | G14: =SQRT(SUM($F$2:F14)/A14) -> 1633.7502 | H14: =IF(ABS(E14)/C14>0.2,0,1) -> 0 | I14: =IF(ABS(E14)/C14>0.1,0,1) -> 0
A15: 14 | B15: 7 | C15: 5000 | D15: 5403 | E15: =ABS(C15-D15) -> 403 | F15: =POWER(E15,2) -> 162409 | G15: =SQRT(SUM($F$2:F15)/A15) -> 1578.0011 | H15: =IF(ABS(E15)/C15>0.2,0,1) -> 1 | I15: =IF(ABS(E15)/C15>0.1,0,1) -> 1
A16: 15 | B16: 4 | C16: 5000 | D16: 3528 | E16: =ABS(C16-D16) -> 1472 | F16: =POWER(E16,2) -> 2166784 | G16: =SQRT(SUM($F$2:F16)/A16) -> 1571.1569 | H16: =IF(ABS(E16)/C16>0.2,0,1) -> 0 | I16: =IF(ABS(E16)/C16>0.1,0,1) -> 0
A17: 16 | B17: 7 | C17: 5000 | D17: 6028 | E17: =ABS(C17-D17) -> 1028 | F17: =POWER(E17,2) -> 1056784 | G17: =SQRT(SUM($F$2:F17)/A17) -> 1542.822 | H17: =IF(ABS(E17)/C17>0.2,0,1) -> 0 | I17: =IF(ABS(E17)/C17>0.1,0,1) -> 0
A18: 17 | B18: 4 | C18: 5000 | D18: 3491 | E18: =ABS(C18-D18) -> 1509 | F18: =POWER(E18,2) -> 2277081 | G18: =SQRT(SUM($F$2:F18)/A18) -> 1540.853 | H18: =IF(ABS(E18)/C18>0.2,0,1) -> 0 | I18: =IF(ABS(E18)/C18>0.1,0,1) -> 0
A19: 18 | B19: 7 | C19: 5000 | D19: 5782 | E19: =ABS(C19-D19) -> 782 | F19: =POWER(E19,2) -> 611524 | G19: =SQRT(SUM($F$2:F19)/A19) -> 1508.7412 | H19: =IF(ABS(E19)/C19>0.2,0,1) -> 1 | I19: =IF(ABS(E19)/C19>0.1,0,1) -> 0
A20: 19 | B20: 4 | C20: 5000 | D20: 3545 | E20: =ABS(C20-D20) -> 1455 | F20: =POWER(E20,2) -> 2117025 | G20: =SQRT(SUM($F$2:F20)/A20) -> 1505.9605 | H20: =IF(ABS(E20)/C20>0.2,0,1) -> 0 | I20: =IF(ABS(E20)/C20>0.1,0,1) -> 0
A21: 20 | B21: 7 | C21: 5000 | D21: 5777 | E21: =ABS(C21-D21) -> 777 | F21: =POWER(E21,2) -> 603729 | G21: =SQRT(SUM($F$2:F21)/A21) -> 1478.0757 | H21: =IF(ABS(E21)/C21>0.2,0,1) -> 1 | I21: =IF(ABS(E21)/C21>0.1,0,1) -> 0
A22: 21 | B22: 4 | C22: 5000 | D22: 3581 | E22: =ABS(C22-D22) -> 1419 | F22: =POWER(E22,2) -> 2013561 | G22: =SQRT(SUM($F$2:F22)/A22) -> 1475.3162 | H22: =IF(ABS(E22)/C22>0.2,0,1) -> 0 | I22: =IF(ABS(E22)/C22>0.1,0,1) -> 0
A23: 22 | B23: 7 | C23: 5000 | D23: 4995 | E23: =ABS(C23-D23) -> 5 | F23: =POWER(E23,2) -> 25 | G23: =SQRT(SUM($F$2:F23)/A23) -> 1441.3967 | H23: =IF(ABS(E23)/C23>0.2,0,1) -> 1 | I23: =IF(ABS(E23)/C23>0.1,0,1) -> 1
... A2501: 2500 | B2501: 4 | C2501: 5000 | D2501: 3564 | E2501: =ABS(C2501-D2501) -> 1436 | F2501: =POWER(E2501,2) -> 2062096 | G2501: =SQRT(SUM($F$2:F2501)/A2501) -> 1242.6917 | H2501: =IF(ABS(E2501)/C2501>0.2,0,1) -> 0 | I2501: =IF(ABS(E2501)/C2501>0.1,0,1) -> 0

Sheet vevolution
A1: # | B1: PC | C1: Setpoint | D1: Rate | E1: Error | F1: Error^2 | G1: RMSE | H1: Goal Range (20%) | I1: Goal Range (10%) | K1: Sample | L1: Steady-state Time (s)
A2: 1 | B2: 1 | C2: 5000 | D2: 1811 | E2: =ABS(C2-D2) -> 3189 | F2: =POWER(E2,2) -> 10169721 | G2: =SQRT(SUM($F$2:F2)/A2) -> 3189 | H2: =IF(ABS(E2)/C2>0.2,0,1) -> 0 | I2: =IF(ABS(E2)/C2>0.1,0,1) -> 0 | K2: 1 | L2: 11
A3: 2 | B3: 4 | C3: 5000 | D3: 3745 | E3: =ABS(C3-D3) -> 1255 | F3: =POWER(E3,2) -> 1575025 | G3: =SQRT(SUM($F$2:F3)/A3) -> 2423.298 | H3: =IF(ABS(E3)/C3>0.2,0,1) -> 0 | I3: =IF(ABS(E3)/C3>0.1,0,1) -> 0 | K3: 300 | L3: 11
A4: 3 | B4: 2 | C4: 5000 | D4: 1446 | E4: =ABS(C4-D4) -> 3554 | F4: =POWER(E4,2) -> 12630916 | G4: =SQRT(SUM($F$2:F4)/A4) -> 2850.4773 | H4: =IF(ABS(E4)/C4>0.2,0,1) -> 0 | I4: =IF(ABS(E4)/C4>0.1,0,1) -> 0 | K4: 600 | L4: 11
A5: 4 | B5: 6 | C5: 5000 | D5: 3458 | E5: =ABS(C5-D5) -> 1542 | F5: =POWER(E5,2) -> 2377764 | G5: =SQRT(SUM($F$2:F5)/A5) -> 2586.1857 | H5: =IF(ABS(E5)/C5>0.2,0,1) -> 0 | I5: =IF(ABS(E5)/C5>0.1,0,1) -> 0 | K5: 900 | L5: 13
A6: 5 | B6: 4 | C6: 5000 | D6: 1297 | E6: =ABS(C6-D6) -> 3703 | F6: =POWER(E6,2) -> 13712209 | G6: =SQRT(SUM($F$2:F6)/A6) -> 2844.8422 | H6: =IF(ABS(E6)/C6>0.2,0,1) -> 0 | I6: =IF(ABS(E6)/C6>0.1,0,1) -> 0 | K6: 1200 | L6: 10
A7: 6 | B7: 7 | C7: 5000 | D7: 5119 | E7: =ABS(C7-D7) -> 119 | F7: =POWER(E7,2) -> 14161 | G7: =SQRT(SUM($F$2:F7)/A7) -> 2597.4281 | H7: =IF(ABS(E7)/C7>0.2,0,1) -> 1 | I7: =IF(ABS(E7)/C7>0.1,0,1) -> 1 | K7: 1500 | L7: 13
A8: 7 | B8: 4 | C8: 5000 | D8: 2532 | E8: =ABS(C8-D8) -> 2468 | F8: =POWER(E8,2) -> 6091024 | G8: =SQRT(SUM($F$2:F8)/A8) -> 2579.336 | H8: =IF(ABS(E8)/C8>0.2,0,1) -> 0 | I8: =IF(ABS(E8)/C8>0.1,0,1) -> 0 | K8: 1800 | L8: 14
A9: 8 | B9: 7 | C9: 5000 | D9: 5009 | E9: =ABS(C9-D9) -> 9 | F9: =POWER(E9,2) -> 81 | G9: =SQRT(SUM($F$2:F9)/A9) -> 2412.75 | H9: =IF(ABS(E9)/C9>0.2,0,1) -> 1 | I9: =IF(ABS(E9)/C9>0.1,0,1) -> 1 | K9: 2100 | L9: 14
A10: 9 | B10: 4 | C10: 5000 | D10: 3352 | E10: =ABS(C10-D10) -> 1648 | F10: =POWER(E10,2) -> 2715904 | G10: =SQRT(SUM($F$2:F10)/A10) -> 2340.1521 | H10: =IF(ABS(E10)/C10>0.2,0,1) -> 0 | I10: =IF(ABS(E10)/C10>0.1,0,1) -> 0 | K10: 2400 | L10: 14
A11: 10 | B11: 6 | C11: 5000 | D11: 5021 | E11: =ABS(C11-D11) -> 21 | F11: =POWER(E11,2) -> 441 | G11: =SQRT(SUM($F$2:F11)/A11) -> 2220.0731 | H11: =IF(ABS(E11)/C11>0.2,0,1) -> 1 | I11: =IF(ABS(E11)/C11>0.1,0,1) -> 1 | K11: Mean Time | L11: =AVERAGE(L2:L10) -> 12.333333
A12: 11 | B12: 5 | C12: 5000 | D12: 3448 | E12: =ABS(C12-D12) -> 1552 | F12: =POWER(E12,2) -> 2408704 | G12: =SQRT(SUM($F$2:F12)/A12) -> 2167.8634 | H12: =IF(ABS(E12)/C12>0.2,0,1) -> 0 | I12: =IF(ABS(E12)/C12>0.1,0,1) -> 0
A13: 12 | B13: 7 | C13: 5000 | D13: 5390 | E13: =ABS(C13-D13) -> 390 | F13: =POWER(E13,2) -> 152100 | G13: =SQRT(SUM($F$2:F13)/A13) -> 2078.6223 | H13: =IF(ABS(E13)/C13>0.2,0,1) -> 1 | I13: =IF(ABS(E13)/C13>0.1,0,1) -> 1
A14: 13 | B14: 5 | C14: 5000 | D14: 3502 | E14: =ABS(C14-D14) -> 1498 | F14: =POWER(E14,2) -> 2244004 | G14: =SQRT(SUM($F$2:F14)/A14) -> 2039.8351 | H14: =IF(ABS(E14)/C14>0.2,0,1) -> 0 | I14: =IF(ABS(E14)/C14>0.1,0,1) -> 0
A15: 14 | B15: 7 | C15: 5000 | D15: 5062 | E15: =ABS(C15-D15) -> 62 | F15: =POWER(E15,2) -> 3844 | G15: =SQRT(SUM($F$2:F15)/A15) -> 1965.7041 | H15: =IF(ABS(E15)/C15>0.2,0,1) -> 1 | I15: =IF(ABS(E15)/C15>0.1,0,1) -> 1
A16: 15 | B16: 5 | C16: 5000 | D16: 4133 | E16: =ABS(C16-D16) -> 867 | F16: =POWER(E16,2) -> 751689 | G16: =SQRT(SUM($F$2:F16)/A16) -> 1912.1992 | H16: =IF(ABS(E16)/C16>0.2,0,1) -> 1 | I16: =IF(ABS(E16)/C16>0.1,0,1) -> 0
A17: 16 | B17: 7 | C17: 5000 | D17: 4742 | E17: =ABS(C17-D17) -> 258 | F17: =POWER(E17,2) -> 66564 | G17: =SQRT(SUM($F$2:F17)/A17) -> 1852.6021 | H17: =IF(ABS(E17)/C17>0.2,0,1) -> 1 | I17: =IF(ABS(E17)/C17>0.1,0,1) -> 1
A18: 17 | B18: 6 | C18: 5000 | D18: 4624 | E18: =ABS(C18-D18) -> 376 | F18: =POWER(E18,2) -> 141376 | G18: =SQRT(SUM($F$2:F18)/A18) -> 1799.6001 | H18: =IF(ABS(E18)/C18>0.2,0,1) -> 1 | I18: =IF(ABS(E18)/C18>0.1,0,1) -> 1
A19: 18 | B19: 6 | C19: 5000 | D19: 4663 | E19: =ABS(C19-D19) -> 337 | F19: =POWER(E19,2) -> 113569 | G19: =SQRT(SUM($F$2:F19)/A19) -> 1750.6998 | H19: =IF(ABS(E19)/C19>0.2,0,1) -> 1 | I19: =IF(ABS(E19)/C19>0.1,0,1) -> 1
A20: 19 | B20: 6 | C20: 5000 | D20: 4580 | E20: =ABS(C20-D20) -> 420 | F20: =POWER(E20,2) -> 176400 | G20: =SQRT(SUM($F$2:F20)/A20) -> 1706.7281 | H20: =IF(ABS(E20)/C20>0.2,0,1) -> 1 | I20: =IF(ABS(E20)/C20>0.1,0,1) -> 1
A21: 20 | B21: 7 | C21: 5000 | D21: 6443 | E21: =ABS(C21-D21) -> 1443 | F21: =POWER(E21,2) -> 2082249 | G21: =SQRT(SUM($F$2:F21)/A21) -> 1694.5168 | H21: =IF(ABS(E21)/C21>0.2,0,1) -> 0 | I21: =IF(ABS(E21)/C21>0.1,0,1) -> 0
A22: 21 | B22: 4 | C22: 5000 | D22: 4749 | E22: =ABS(C22-D22) -> 251 | F22: =POWER(E22,2) -> 63001 | G22: =SQRT(SUM($F$2:F22)/A22) -> 1654.5859 | H22: =IF(ABS(E22)/C22>0.2,0,1) -> 1 | I22: =IF(ABS(E22)/C22>0.1,0,1) -> 1
A23: 22 | B23: 6 | C23: 5000 | D23: 3435 | E23: =ABS(C23-D23) -> 1565 | F23: =POWER(E23,2) -> 2449225 | G23: =SQRT(SUM($F$2:F23)/A23) -> 1650.6193 | H23: =IF(ABS(E23)/C23>0.2,0,1) -> 0 | I23: =IF(ABS(E23)/C23>0.1,0,1) -> 0
... A2501: 2500 | B2501: 7 | C2501: 5000 | D2501: 4879 | E2501: =ABS(C2501-D2501) -> 121 | F2501: =POWER(E2501,2) -> 14641 | G2501: =SQRT(SUM($F$2:F2501)/A2501) -> 1027.6428 | H2501: =IF(ABS(E2501)/C2501>0.2,0,1) -> 1 | I2501: =IF(ABS(E2501)/C2501>0.1,0,1) -> 1

Sheet vpso
A1: # | B1: PC | C1: Setpoint | D1: Rate | E1: Error | F1: Error^2 | G1: RMSE | H1: Goal Range (20%) | I1: Goal Range (10%) | K1: Sample | L1: Steady-state Time (s)
A2: c | B2: 1 | C2: 5000 | D2: 1411 | E2: =ABS(C2-D2) -> 3589 | F2: =POWER(E2,2) -> 12880921 | G2: =SQRT(SUM($F$2:F2)/A2) -> #VALUE! | H2: =IF(ABS(E2)/C2>0.2,0,1) -> 0 | I2: =IF(ABS(E2)/C2>0.1,0,1) -> 0 | K2: 1 | L2: 6
A3: 2 | B3: 5 | C3: 5000 | D3: 4407 | E3: =ABS(C3-D3) -> 593 | F3: =POWER(E3,2) -> 351649 | G3: =SQRT(SUM($F$2:F3)/A3) -> 2572.214 | H3: =IF(ABS(E3)/C3>0.2,0,1) -> 1 | I3: =IF(ABS(E3)/C3>0.1,0,1) -> 0 | K3: 300 | L3: 8
A4: 3 | B4: 2 | C4: 5000 | D4: 1735 | E4: =ABS(C4-D4) -> 3265 | F4: =POWER(E4,2) -> 10660225 | G4: =SQRT(SUM($F$2:F4)/A4) -> 2822.1029 | H4: =IF(ABS(E4)/C4>0.2,0,1) -> 0 | I4: =IF(ABS(E4)/C4>0.1,0,1) -> 0 | K4: 600 | L4: 13
A5: 4 | B5: 5 | C5: 5000 | D5: 4321 | E5: =ABS(C5-D5) -> 679 | F5: =POWER(E5,2) -> 461041 | G5: =SQRT(SUM($F$2:F5)/A5) -> 2467.4803 | H5: =IF(ABS(E5)/C5>0.2,0,1) -> 1 | I5: =IF(ABS(E5)/C5>0.1,0,1) -> 0 | K5: 900 | L5: 11
A6: 5 | B6: 3 | C6: 5000 | D6: 2578 | E6: =ABS(C6-D6) -> 2422 | F6: =POWER(E6,2) -> 5866084 | G6: =SQRT(SUM($F$2:F6)/A6) -> 2458.4515 | H6: =IF(ABS(E6)/C6>0.2,0,1) -> 0 | I6: =IF(ABS(E6)/C6>0.1,0,1) -> 0 | K6: 1200 | L6: 15
A7: 6 | B7: 5 | C7: 5000 | D7: 3901 | E7: =ABS(C7-D7) -> 1099 | F7: =POWER(E7,2) -> 1207801 | G7: =SQRT(SUM($F$2:F7)/A7) -> 2288.6576 | H7: =IF(ABS(E7)/C7>0.2,0,1) -> 0 | I7: =IF(ABS(E7)/C7>0.1,0,1) -> 0 | K7: 1500 | L7: 14
A8: 7 | B8: 4 | C8: 5000 | D8: 3141 | E8: =ABS(C8-D8) -> 1859 | F8: =POWER(E8,2) -> 3455881 | G8: =SQRT(SUM($F$2:F8)/A8) -> 2232.3467 | H8: =IF(ABS(E8)/C8>0.2,0,1) -> 0 | I8: =IF(ABS(E8)/C8>0.1,0,1) -> 0 | K8: 1800 | L8: 14
A9: 8 | B9: 6 | C9: 5000 | D9: 5022 | E9: =ABS(C9-D9) -> 22 | F9: =POWER(E9,2) -> 484 | G9: =SQRT(SUM($F$2:F9)/A9) -> 2088.1836 | H9: =IF(ABS(E9)/C9>0.2,0,1) -> 1 | I9: =IF(ABS(E9)/C9>0.1,0,1) -> 1 | K9: 2100 | L9: 12
A10: 9 | B10: 4 | C10: 5000 | D10: 3219 | E10: =ABS(C10-D10) -> 1781 | F10: =POWER(E10,2) -> 3171961 | G10: =SQRT(SUM($F$2:F10)/A10) -> 2056.3194 | H10: =IF(ABS(E10)/C10>0.2,0,1) -> 0 | I10: =IF(ABS(E10)/C10>0.1,0,1) -> 0 | K10: 2400 | L10: 16
A11: 10 | B11: 6 | C11: 5000 | D11: 5023 | E11: =ABS(C11-D11) -> 23 | F11: =POWER(E11,2) -> 529 | G11: =SQRT(SUM($F$2:F11)/A11) -> 1950.8095 | H11: =IF(ABS(E11)/C11>0.2,0,1) -> 1 | I11: =IF(ABS(E11)/C11>0.1,0,1) -> 1 | K11: Mean Time | L11: =AVERAGE(L2:L10) -> 12.111111
A12: 11 | B12: 4 | C12: 5000 | D12: 3398 | E12: =ABS(C12-D12) -> 1602 | F12: =POWER(E12,2) -> 2566404 | G12: =SQRT(SUM($F$2:F12)/A12) -> 1921.7175 | H12: =IF(ABS(E12)/C12>0.2,0,1) -> 0 | I12: =IF(ABS(E12)/C12>0.1,0,1) -> 0
A13: 12 | B13: 6 | C13: 5000 | D13: 4978 | E13: =ABS(C13-D13) -> 22 | F13: =POWER(E13,2) -> 484 | G13: =SQRT(SUM($F$2:F13)/A13) -> 1839.9154 | H13: =IF(ABS(E13)/C13>0.2,0,1) -> 1 | I13: =IF(ABS(E13)/C13>0.1,0,1) -> 1
A14: 13 | B14: 5 | C14: 5000 | D14: 4003 | E14: =ABS(C14-D14) -> 997 | F14: =POWER(E14,2) -> 994009 | G14: =SQRT(SUM($F$2:F14)/A14) -> 1789.23 | H14: =IF(ABS(E14)/C14>0.2,0,1) -> 1 | I14: =IF(ABS(E14)/C14>0.1,0,1) -> 0
A15: 14 | B15: 6 | C15: 5000 | D15: 4267 | E15: =ABS(C15-D15) -> 733 | F15: =POWER(E15,2) -> 537289 | G15: =SQRT(SUM($F$2:F15)/A15) -> 1735.239 | H15: =IF(ABS(E15)/C15>0.2,0,1) -> 1 | I15: =IF(ABS(E15)/C15>0.1,0,1) -> 0
A16: 15 | B16: 6 | C16: 5000 | D16: 4734 | E16: =ABS(C16-D16) -> 266 | F16: =POWER(E16,2) -> 70756 | G16: =SQRT(SUM($F$2:F16)/A16) -> 1677.8065 | H16: =IF(ABS(E16)/C16>0.2,0,1) -> 1 | I16: =IF(ABS(E16)/C16>0.1,0,1) -> 1
A17: 16 | B17: 6 | C17: 5000 | D17: 4404 | E17: =ABS(C17-D17) -> 596 | F17: =POWER(E17,2) -> 355216 | G17: =SQRT(SUM($F$2:F17)/A17) -> 1631.3479 | H17: =IF(ABS(E17)/C17>0.2,0,1) -> 1 | I17: =IF(ABS(E17)/C17>0.1,0,1) -> 0
A18: 17 | B18: 6 | C18: 5000 | D18: 4715 | E18: =ABS(C18-D18) -> 285 | F18: =POWER(E18,2) -> 81225 | G18: =SQRT(SUM($F$2:F18)/A18) -> 1584.1487 | H18: =IF(ABS(E18)/C18>0.2,0,1) -> 1 | I18: =IF(ABS(E18)/C18>0.1,0,1) -> 1
A19: 18 | B19: 6 | C19: 5000 | D19: 4727 | E19: =ABS(C19-D19) -> 273 | F19: =POWER(E19,2) -> 74529 | G19: =SQRT(SUM($F$2:F19)/A19) -> 1540.8599 | H19: =IF(ABS(E19)/C19>0.2,0,1) -> 1 | I19: =IF(ABS(E19)/C19>0.1,0,1) -> 1
A20: 19 | B20: 6 | C20: 5000 | D20: 4804 | E20: =ABS(C20-D20) -> 196 | F20: =POWER(E20,2) -> 38416 | G20: =SQRT(SUM($F$2:F20)/A20) -> 1500.4368 | H20: =IF(ABS(E20)/C20>0.2,0,1) -> 1 | I20: =IF(ABS(E20)/C20>0.1,0,1) -> 1
A21: 20 | B21: 6 | C21: 5000 | D21: 4988 | E21: =ABS(C21-D21) -> 12 | F21: =POWER(E21,2) -> 144 | G21: =SQRT(SUM($F$2:F21)/A21) -> 1462.4474 | H21: =IF(ABS(E21)/C21>0.2,0,1) -> 1 | I21: =IF(ABS(E21)/C21>0.1,0,1) -> 1
A22: 21 | B22: 6 | C22: 5000 | D22: 4268 | E22: =ABS(C22-D22) -> 732 | F22: =POWER(E22,2) -> 535824 | G22: =SQRT(SUM($F$2:F22)/A22) -> 1436.1137 | H22: =IF(ABS(E22)/C22>0.2,0,1) -> 1 | I22: =IF(ABS(E22)/C22>0.1,0,1) -> 0
A23: 22 | B23: 7 | C23: 5000 | D23: 5899 | E23: =ABS(C23-D23) -> 899 | F23: =POWER(E23,2) -> 808201 | G23: =SQRT(SUM($F$2:F23)/A23) -> 1416.1258 | H23: =IF(ABS(E23)/C23>0.2,0,1) -> 1 | I23: =IF(ABS(E23)/C23>0.1,0,1) -> 0
... A2501: 2500 | B2501: 7 | C2501: 5000 | D2501: 5058 | E2501: =ABS(C2501-D2501) -> 58 | F2501: =POWER(E2501,2) -> 3364 | G2501: =SQRT(SUM($F$2:F2501)/A2501) -> 1024.0307 | H2501: =IF(ABS(E2501)/C2501>0.2,0,1) -> 1 | I2501: =IF(ABS(E2501)/C2501>0.1,0,1) -> 1

Sheet vstatic
A1: # | B1: PC | C1: Setpoint | D1: Rate | E1: Error | F1: Error^2 | G1: RMSE | H1: Goal Range (20%) | I1: Goal Range (10%) | K1: Sample | L1: Steady-state Time (s)
A2: 1 | B2: 1 | C2: 5000 | D2: 1455 | E2: =ABS(C2-D2) -> 3545 | F2: =POWER(E2,2) -> 12567025 | G2: =SQRT(SUM($F$2:F2)/A2) -> 3545 | H2: =IF(ABS(E2)/C2>0.2,0,1) -> 0 | I2: =IF(ABS(E2)/C2>0.1,0,1) -> 0 | K2: 1 | L2: 0
A3: 2 | B3: 4 | C3: 5000 | D3: 4456 | E3: =ABS(C3-D3) -> 544 | F3: =POWER(E3,2) -> 295936 | G3: =SQRT(SUM($F$2:F3)/A3) -> 2536.0364 | H3: =IF(ABS(E3)/C3>0.2,0,1) -> 1 | I3: =IF(ABS(E3)/C3>0.1,0,1) -> 0 | K3: 300 | L3: 0
A4: 3 | B4: 2 | C4: 5000 | D4: 2447 | E4: =ABS(C4-D4) -> 2553 | F4: =POWER(E4,2) -> 6517809 | G4: =SQRT(SUM($F$2:F4)/A4) -> 2541.7035 | H4: =IF(ABS(E4)/C4>0.2,0,1) -> 0 | I4: =IF(ABS(E4)/C4>0.1,0,1) -> 0 | K4: 600 | L4: 0
A5: 4 | B5: 4 | C5: 5000 | D5: 4128 | E5: =ABS(C5-D5) -> 872 | F5: =POWER(E5,2) -> 760384 | G5: =SQRT(SUM($F$2:F5)/A5) -> 2243.9449 | H5: =IF(ABS(E5)/C5>0.2,0,1) -> 1 | I5: =IF(ABS(E5)/C5>0.1,0,1) -> 0 | K5: 900 | L5: 0
A6: 5 | B6: 3 | C6: 5000 | D6: 3233 | E6: =ABS(C6-D6) -> 1767 | F6: =POWER(E6,2) -> 3122289 | G6: =SQRT(SUM($F$2:F6)/A6) -> 2157.0092 | H6: =IF(ABS(E6)/C6>0.2,0,1) -> 0 | I6: =IF(ABS(E6)/C6>0.1,0,1) -> 0 | K6: 1200 | L6: 0
A7: 6 | B7: 4 | C7: 5000 | D7: 3785 | E7: =ABS(C7-D7) -> 1215 | F7: =POWER(E7,2) -> 1476225 | G7: =SQRT(SUM($F$2:F7)/A7) -> 2030.5856 | H7: =IF(ABS(E7)/C7>0.2,0,1) -> 0 | I7: =IF(ABS(E7)/C7>0.1,0,1) -> 0 | K7: 1500 | L7: 0
A8: 7 | B8: 4 | C8: 5000 | D8: 3363 | E8: =ABS(C8-D8) -> 1637 | F8: =POWER(E8,2) -> 2679769 | G8: =SQRT(SUM($F$2:F8)/A8) -> 1979.157 | H8: =IF(ABS(E8)/C8>0.2,0,1) -> 0 | I8: =IF(ABS(E8)/C8>0.1,0,1) -> 0 | K8: 1800 | L8: 0
A9: 8 | B9: 5 | C9: 5000 | D9: 3812 | E9: =ABS(C9-D9) -> 1188 | F9: =POWER(E9,2) -> 1411344 | G9: =SQRT(SUM($F$2:F9)/A9) -> 1898.3803 | H9: =IF(ABS(E9)/C9>0.2,0,1) -> 0 | I9: =IF(ABS(E9)/C9>0.1,0,1) -> 0 | K9: 2100 | L9: 0
A10: 9 | B10: 5 | C10: 5000 | D10: 3817 | E10: =ABS(C10-D10) -> 1183 | F10: =POWER(E10,2) -> 1399489 | G10: =SQRT(SUM($F$2:F10)/A10) -> 1832.7354 | H10: =IF(ABS(E10)/C10>0.2,0,1) -> 0 | I10: =IF(ABS(E10)/C10>0.1,0,1) -> 0 | K10: 2400 | L10: 0
A11: 10 | B11: 5 | C11: 5000 | D11: 3960 | E11: =ABS(C11-D11) -> 1040 | F11: =POWER(E11,2) -> 1081600 | G11: =SQRT(SUM($F$2:F11)/A11) -> 1769.516 | H11: =IF(ABS(E11)/C11>0.2,0,1) -> 0 | I11: =IF(ABS(E11)/C11>0.1,0,1) -> 0 | K11: Mean Time | L11: 6
A12: 11 | B12: 5 | C12: 5000 | D12: 3675 | E12: =ABS(C12-D12) -> 1325 | F12: =POWER(E12,2) -> 1755625 | G12: =SQRT(SUM($F$2:F12)/A12) -> 1733.8212 | H12: =IF(ABS(E12)/C12>0.2,0,1) -> 0 | I12: =IF(ABS(E12)/C12>0.1,0,1) -> 0
A13: 12 | B13: 6 | C13: 5000 | D13: 4854 | E13: =ABS(C13-D13) -> 146 | F13: =POWER(E13,2) -> 21316 | G13: =SQRT(SUM($F$2:F13)/A13) -> 1660.5424 | H13: =IF(ABS(E13)/C13>0.2,0,1) -> 1 | I13: =IF(ABS(E13)/C13>0.1,0,1) -> 1
A14: 13 | B14: 5 | C14: 5000 | D14: 4213 | E14: =ABS(C14-D14) -> 787 | F14: =POWER(E14,2) -> 619369 | G14: =SQRT(SUM($F$2:F14)/A14) -> 1610.2599 | H14: =IF(ABS(E14)/C14>0.2,0,1) -> 1 | I14: =IF(ABS(E14)/C14>0.1,0,1) -> 0
A15: 14 | B15: 6 | C15: 5000 | D15: 4971 | E15: =ABS(C15-D15) -> 29 | F15: =POWER(E15,2) -> 841 | G15: =SQRT(SUM($F$2:F15)/A15) -> 1551.7046 | H15: =IF(ABS(E15)/C15>0.2,0,1) -> 1 | I15: =IF(ABS(E15)/C15>0.1,0,1) -> 1
A16: 15 | B16: 5 | C16: 5000 | D16: 4188 | E16: =ABS(C16-D16) -> 812 | F16: =POWER(E16,2) -> 659344 | G16: =SQRT(SUM($F$2:F16)/A16) -> 1513.6791 | H16: =IF(ABS(E16)/C16>0.2,0,1) -> 1 | I16: =IF(ABS(E16)/C16>0.1,0,1) -> 0
A17: 16 | B17: 6 | C17: 5000 | D17: 4244 | E17: =ABS(C17-D17) -> 756 | F17: =POWER(E17,2) -> 571536 | G17: =SQRT(SUM($F$2:F17)/A17) -> 1477.7496 | H17: =IF(ABS(E17)/C17>0.2,0,1) -> 1 | I17: =IF(ABS(E17)/C17>0.1,0,1) -> 0
A18: 17 | B18: 6 | C18: 5000 | D18: 4606 | E18: =ABS(C18-D18) -> 394 | F18: =POWER(E18,2) -> 155236 | G18: =SQRT(SUM($F$2:F18)/A18) -> 1436.8089 | H18: =IF(ABS(E18)/C18>0.2,0,1) -> 1 | I18: =IF(ABS(E18)/C18>0.1,0,1) -> 1
A19: 18 | B19: 6 | C19: 5000 | D19: 4817 | E19: =ABS(C19-D19) -> 183 | F19: =POWER(E19,2) -> 33489 | G19: =SQRT(SUM($F$2:F19)/A19) -> 1396.9933 | H19: =IF(ABS(E19)/C19>0.2,0,1) -> 1 | I19: =IF(ABS(E19)/C19>0.1,0,1) -> 1
A20: 19 | B20: 6 | C20: 5000 | D20: 4779 | E20: =ABS(C20-D20) -> 221 | F20: =POWER(E20,2) -> 48841 | G20: =SQRT(SUM($F$2:F20)/A20) -> 1360.6784 | H20: =IF(ABS(E20)/C20>0.2,0,1) -> 1 | I20: =IF(ABS(E20)/C20>0.1,0,1) -> 1
A21: 20 | B21: 6 | C21: 5000 | D21: 4733 | E21: =ABS(C21-D21) -> 267 | F21: =POWER(E21,2) -> 71289 | G21: =SQRT(SUM($F$2:F21)/A21) -> 1327.5684 | H21: =IF(ABS(E21)/C21>0.2,0,1) -> 1 | I21: =IF(ABS(E21)/C21>0.1,0,1) -> 1
A22: 21 | B22: 6 | C22: 5000 | D22: 4572 | E22: =ABS(C22-D22) -> 428 | F22: =POWER(E22,2) -> 183184 | G22: =SQRT(SUM($F$2:F22)/A22) -> 1298.9362 | H22: =IF(ABS(E22)/C22>0.2,0,1) -> 1 | I22: =IF(ABS(E22)/C22>0.1,0,1) -> 1
A23: 22 | B23: 6 | C23: 5000 | D23: 5022 | E23: =ABS(C23-D23) -> 22 | F23: =POWER(E23,2) -> 484 | G23: =SQRT(SUM($F$2:F23)/A23) -> 1269.0803 | H23: =IF(ABS(E23)/C23>0.2,0,1) -> 1 | I23: =IF(ABS(E23)/C23>0.1,0,1) -> 1
... A2501: 2500 | B2501: 7 | C2501: 5000 | D2501: 1055 | E2501: =ABS(C2501-D2501) -> 3945 | F2501: =POWER(E2501,2) -> 15563025 | G2501: =SQRT(SUM($F$2:F2501)/A2501) -> 1100.3302 | H2501: =IF(ABS(E2501)/C2501>0.2,0,1) -> 0 | I2501: =IF(ABS(E2501)/C2501>0.1,0,1) -> 0

Sheet VSummary
A1: Variable Setpoint
A2: Mode | B2: RMSE | C2: NRMSE (*) | D2: MAE | E2: GR (20%) | F2: GR (10%) | H2: RMSE (300) | I2: RMSE(600) | J2: RMSE(900) | K2: RMSE(1200) | L2: RMSE(1500) | M2: RMSE(1800) | N2: RMSE(2100) | O2: RMSE(2400)
A3: Optuna | B3: =voptuna!$G$2501 -> 1044.0186 | C3: =B3/(LARGE(voptuna!$D$2:$D$2501,1)-SMALL(voptuna!$D$2:$D$2501,1)) -> 0.091085204 | D3: =SUM(voptuna!$E$2:$E$2501)/$B$14 -> 709.0684 | E3: =COUNTIF(voptuna!H2:H2501,1)/$B$14 -> 0.8364 | F3: =COUNTIF(voptuna!I2:I2501,1)/$B$14 -> 0.6016 | H3: =SQRT(SUM(voptuna!$F$2:$F$301)/300) -> 1073.3326 | I3: =SQRT(SUM(voptuna!$F$302:$F$601)/300) -> 1025.6417 | J3: =SQRT(SUM(voptuna!$F$602:$F$901)/300) -> 916.18788 | K3: =SQRT(SUM(voptuna!$F$902:$F$1201)/300) -> 955.12173 | L3: =SQRT(SUM(voptuna!$F$1202:$F$1501)/300) -> 966.33736 | M3: =SQRT(SUM(voptuna!$F$1502:$F$1801)/300) -> 1066.979 | N3: =SQRT(SUM(voptuna!$F$1802:$F$2101)/300) -> 1143.624 | O3: =SQRT(SUM(voptuna!$F$2102:$F$2401)/300) -> 1072.661
A4: RL | B4: =vrl!$G$2501 -> 995.46239 | C4: =B3/(LARGE(vrl!$D$2:$D$2501,1)-SMALL(vrl!$D$2:$D$2501,1)) -> 0.09895911 | D4: =SUM(vrl!E2:E2501)/$B$14 -> 661.8848 | E4: =COUNTIF(vrl!H2:H2501,1)/$B$14 -> 0.8732 | F4: =COUNTIF(vrl!I2:I2501,1)/$B$14 -> 0.6332 | H4: =SQRT(SUM(vrl!$F$2:$F$301)/300) -> 1078.1575 | I4: =SQRT(SUM(vrl!$F$302:$F$601)/300) -> 941.94242 | J4: =SQRT(SUM(vrl!$F$602:$F$901)/300) -> 891.40877 | K4: =SQRT(SUM(vrl!$F$902:$F$1201)/300) -> 960.17611 | L4: =SQRT(SUM(vrl!$F$1202:$F$1501)/300) -> 999.15132 | M4: =SQRT(SUM(vrl!$F$1502:$F$1801)/300) -> 1030.964 | N4: =SQRT(SUM(vrl!$F$1802:$F$2101)/300) -> 966.09545 | O4: =SQRT(SUM(vrl!$F$2102:$F$2401)/300) -> 1041.9397
A5: SPSA | B5: =vspsa!$G$2501 -> 1130.0448 | C5: =B3/(LARGE(vspsa!$D$2:$D$2501,1)-SMALL(vspsa!$D$2:$D$2501,1)) -> 0.088807299 | D5: =SUM(vspsa!E2:E2501)/$B$14 -> 750.0788 | E5: =COUNTIF(vspsa!H2:H2501,1)/$B$14 -> 0.8452 | F5: =COUNTIF(vspsa!$I$2:$I$2501,1)/$B$14 -> 0.5924 | H5: =SQRT(SUM(vspsa!$F$2:$F$301)/300) -> 975.94892 | I5: =SQRT(SUM(vspsa!$F$302:$F$601)/300) -> 1113.1299 | J5: =SQRT(SUM(vspsa!$F$602:$F$901)/300) -> 1080.0419 | K5: =SQRT(SUM(vspsa!$F$902:$F$1201)/300) -> 851.81819 | L5: =SQRT(SUM(vspsa!$F$1202:$F$1501)/300) -> 1691.6528 | M5: =SQRT(SUM(vspsa!$F$1502:$F$1801)/300) -> 1012.8813 | N5: =SQRT(SUM(vspsa!$F$1802:$F$2101)/300) -> 1077.9553 | O5: =SQRT(SUM(vspsa!$F$2102:$F$2401)/300) -> 1057.2124
A6: Bayes | B6: =vbayes!$G$2501 -> 1242.6917 | C6: =B3/(LARGE(vbayes!$D$2:$D$2501,1)-SMALL(vbayes!$D$2:$D$2501,1)) -> 0.086518489 | D6: =SUM(vbayes!E2:E2501)/$B$14 -> 880.1364 | E6: =COUNTIF(vbayes!H2:H2501,1)/$B$14 -> 0.7672 | F6: =COUNTIF(vbayes!$I$2:$I$2501,1)/$B$14 -> 0.5008 | H6: =SQRT(SUM(vbayes!$F$2:$F$301)/300) -> 1137.6226 | I6: =SQRT(SUM(vbayes!$F$302:$F$601)/300) -> 1135.6334 | J6: =SQRT(SUM(vbayes!$F$602:$F$901)/300) -> 1022.9701 | K6: =SQRT(SUM(vbayes!$F$902:$F$1201)/300) -> 1208.4258 | L6: =SQRT(SUM(vbayes!$F$1202:$F$1501)/300) -> 1345.006 | M6: =SQRT(SUM(vbayes!$F$1502:$F$1801)/300) -> 1234.8595 | N6: =SQRT(SUM(vbayes!$F$1802:$F$2101)/300) -> 1241.0932 | O6: =SQRT(SUM(vbayes!$F$2102:$F$2401)/300) -> 1421.3821
A7: Evolution | B7: =vevolution!$G$2501 -> 1027.6428 | C7: =B3/(LARGE(vevolution!$D$2:$D$2501,1)-SMALL(vevolution!$D$2:$D$2501,1)) -> 0.09529195 | D7: =SUM(vevolution!E2:E2501)/$B$14 -> 658.7328 | E7: =COUNTIF(vevolution!H2:H2501,1)/$B$14 -> 0.876 | F7: =COUNTIF(vevolution!$I$2:$I$2501,1)/$B$14 -> 0.6584 | H7: =SQRT(SUM(vevolution!$F$2:$F$301)/300) -> 999.40862 | I7: =SQRT(SUM(vevolution!$F$302:$F$601)/300) -> 976.42966 | J7: =SQRT(SUM(vevolution!$F$602:$F$901)/300) -> 956.16547 | K7: =SQRT(SUM(vevolution!$F$902:$F$1201)/300) -> 1036.7018 | L7: =SQRT(SUM(vevolution!$F$1202:$F$1501)/300) -> 980.2681 | M7: =SQRT(SUM(vevolution!$F$1502:$F$1801)/300) -> 1085.4287 | N7: =SQRT(SUM(vevolution!$F$1802:$F$2101)/300) -> 1051.9799 | O7: =SQRT(SUM(vevolution!$F$2102:$F$2401)/300) -> 1142.7389
A8: PSO | B8: =vpso!$G$2501 -> 1024.0307 | C8: =B3/(LARGE(vpso!$D$2:$D$2501,1)-SMALL(vpso!$D$2:$D$2501,1)) -> 0.09735347 | D8: =SUM(vpso!E2:E2501)/$B$14 -> 670.7004 | E8: =COUNTIF(vpso!H2:H2501,1)/$B$14 -> 0.8752 | F8: =COUNTIF(vpso!$I$2:$I$2501,1)/$B$14 -> 0.6384 | H8: =SQRT(SUM(vpso!$F$2:$F$301)/300) -> 1117.9537 | I8: =SQRT(SUM(vpso!$F$302:$F$601)/300) -> 1071.7046 | J8: =SQRT(SUM(vpso!$F$602:$F$901)/300) -> 987.2745 | K8: =SQRT(SUM(vpso!$F$902:$F$1201)/300) -> 945.55071 | L8: =SQRT(SUM(vpso!$F$1202:$F$1501)/300) -> 1002.4134 | M8: =SQRT(SUM(vpso!$F$1502:$F$1801)/300) -> 1075.9932 | N8: =SQRT(SUM(vpso!$F$1802:$F$2101)/300) -> 1031.7547 | O8: =SQRT(SUM(vpso!$F$2102:$F$2401)/300) -> 961.87919
A9: Static | B9: =vstatic!$G$2501 -> 1100.3302 | C9: =B3/(LARGE(vstatic!$D$2:$D$2501,1)-SMALL(vstatic!$D$2:$D$2501,1)) -> 0.095860675 | D9: =SUM(vstatic!E2:E2501)/$B$14 -> 729.3124 | E9: =COUNTIF(vstatic!$H$2:$H$2501,1)/$B$14 -> 0.8452 | F9: =COUNTIF(vstatic!$I$2:$I$2501,1)/$B$14 -> 0.5884 | H9: =SQRT(SUM(vstatic!$F$2:$F$301)/300) -> 1055.6116 | I9: =SQRT(SUM(vstatic!$F$302:$F$601)/300) -> 1069.9978 | J9: =SQRT(SUM(vstatic!$F$602:$F$901)/300) -> 1078.1011 | K9: =SQRT(SUM(vstatic!$F$902:$F$1201)/300) -> 1114.0795 | L9: =SQRT(SUM(vstatic!$F$1202:$F$1501)/300) -> 1137.3494 | M9: =SQRT(SUM(vstatic!$F$1502:$F$1801)/300) -> 1205.8764 | N9: =SQRT(SUM(vstatic!$F$1802:$F$2101)/300) -> 1131.7256 | O9: =SQRT(SUM(vstatic!$F$2102:$F$2401)/300) -> 988.85727
A10: (*) Min-Max
H11: Optuna | I11: =voptuna!$G$301 -> 1073.3326 | J11: =voptuna!$G$601 -> 1049.758 | K11: =voptuna!$G$901 -> 1007.2047 | L11: =voptuna!$G$1201 -> 994.43972 | M11: =voptuna!$G$1501 -> 988.88314 | N11: =voptuna!$G$1801 -> 1002.3218 | O11: =voptuna!$G$2101 -> 1023.7026 | P11: =voptuna!$G$2401 -> 1029.9497
A12: Monitor Time (s) | B12: 1 | H12: RL | I12: =vrl!$G$301 -> 1078.1575 | J12: =vrl!$G$601 -> 1012.3436 | K12: =vrl!$G$901 -> 973.70234 | L12: =vrl!$G$1201 -> 970.33846 | M12: =vrl!$G$1501 -> 976.16907 | N12: =vrl!$G$1801 -> 985.51315 | O12: =vrl!$G$2101 -> 982.76268 | P12: =vrl!$G$2401 -> 990.3532
A13: Window Size | B13: 300 | H13: SPSA | I13: =vspsa!$G$301 -> 975.94892 | J13: =vspsa!$G$601 -> 1046.789 | K13: =vspsa!$G$901 -> 1057.9895 | L13: =vspsa!$G$1201 -> 1010.3984 | M13: =vspsa!$G$1501 -> 1178.5846 | N13: =vspsa!$G$1801 -> 1152.6229 | O13: =vspsa!$G$2101 -> 1142.255 | P13: =vspsa!$G$2401 -> 1131.9741
A14: Sample Size | B14: 2500 | H14: Bayes | I14: =vbayes!$G$301 -> 1137.6226 | J14: =vbayes!$G$601 -> 1136.6284 | K14: =vbayes!$G$901 -> 1100.0479 | L14: =vbayes!$G$1201 -> 1128.1189 | M14: =vbayes!$G$1501 -> 1174.7042 | N14: =vbayes!$G$1801 -> 1184.9422 | O14: =vbayes!$G$2101 -> 1193.1256 | P14: =vbayes!$G$2401 -> 1223.9877
A15: Same Level Setpoint | B15: 100 | H15: Evolution | I15: =voptuna!$G$301 -> 1073.3326 | J15: =voptuna!$G$601 -> 1049.758 | K15: =voptuna!$G$901 -> 1007.2047 | L15: =voptuna!$G$1201 -> 994.43972 | M15: =voptuna!$G$1501 -> 988.88314 | N15: =voptuna!$G$1801 -> 1002.3218 | O15: =voptuna!$G$2101 -> 1023.7026 | P15: =voptuna!$G$2401 -> 1029.9497
A16: Jitter | B16: On | H16: PSO | I16: =voptuna!$G$301 -> 1073.3326 | J16: =voptuna!$G$601 -> 1049.758 | K16: =voptuna!$G$901 -> 1007.2047 | L16: =voptuna!$G$1201 -> 994.43972 | M16: =voptuna!$G$1501 -> 988.88314 | N16: =voptuna!$G$1801 -> 1002.3218 | O16: =voptuna!$G$2101 -> 1023.7026 | P16: =voptuna!$G$2401 -> 1029.9497
H17: Static | I17: =voptuna!$G$301 -> 1073.3326 | J17: =voptuna!$G$601 -> 1049.758 | K17: =voptuna!$G$901 -> 1007.2047 | L17: =voptuna!$G$1201 -> 994.43972 | M17: =voptuna!$G$1501 -> 988.88314 | N17: =voptuna!$G$1801 -> 1002.3218 | O17: =voptuna!$G$2101 -> 1023.7026 | P17: =voptuna!$G$2401 -> 1029.9497
A21: /mnt/d/GolandProjects/control-theory/internal/controllers/neural/adaptive-pid-other-options/examples
A22: app/adaptive-pid-other-options/examples/

Sheet FSummary
A1: FIXED Setpoint
A2: Mode | B2: RMSE | C2: NRMSE (*) | D2: MAE | E2: GR (20%) | F2: GR (10%) | H2: RMSE (300) | I2: RMSE(600) | J2: RMSE(900) | K2: RMSE(1200) | L2: RMSE(1500) | M2: RMSE(1800) | N2: RMSE(2100) | O2: RMSE(2400)
A3: Optuna | B3: =foptuna!$H$2501 -> 768.06334 | C3: =B3/(LARGE(foptuna!$D$2:$D$2501,1)-SMALL(foptuna!$D$2:$D$2501,1)) -> 0.087638446 | D3: =SUM(foptuna!$F$2:$F$2501)/$B$14 -> 508.2368 | E3: =COUNTIF(foptuna!I2:I2501,1)/$B$14 -> 0.902 | F3: =COUNTIF(foptuna!J2:J2501,1)/$B$14 -> 0.6416 | H3: =SQRT(SUM(foptuna!$G$2:$G$301)/300) -> 750.65088 | I3: =SQRT(SUM(foptuna!$G$302:$G$601)/300) -> 787.77868 | J3: =SQRT(SUM(foptuna!$G$602:$G$901)/300) -> 788.14389 | K3: =SQRT(SUM(foptuna!$G$902:$G$1201)/300) -> 737.08135 | L3: =SQRT(SUM(foptuna!$G$1202:$G$1501)/300) -> 761.60762 | M3: =SQRT(SUM(foptuna!$G$1502:$G$1801)/300) -> 744.60601 | N3: =SQRT(SUM(foptuna!$G$1802:$G$2101)/300) -> 857.43753 | O3: =SQRT(SUM(foptuna!$G$2102:$G$2401)/300) -> 721.61387
A4: RL | B4: =frl!$H$2501 -> 764.25004 | C4: =B3/(LARGE(frl!$D$2:$D$2501,1)-SMALL(frl!$D$2:$D$2501,1)) -> 0.098343577 | D4: =SUM(frl!F2:F2501)/$B$14 -> 508.4668 | E4: =COUNTIF(frl!I2:I2501,1)/$B$14 -> 0.894 | F4: =COUNTIF(frl!J2:J2501,1)/$B$14 -> 0.6512 | H4: =SQRT(SUM(frl!$G$2:$G$301)/300) -> 757.38275 | I4: =SQRT(SUM(frl!$G$302:$G$601)/300) -> 674.94379 | J4: =SQRT(SUM(frl!$G$602:$G$901)/300) -> 776.00635 | K4: =SQRT(SUM(frl!$G$902:$G$1201)/300) -> 689.73813 | L4: =SQRT(SUM(frl!$G$1202:$G$1501)/300) -> 724.95551 | M4: =SQRT(SUM(frl!$G$1502:$G$1801)/300) -> 782.96438 | N4: =SQRT(SUM(frl!$G$1802:$G$2101)/300) -> 839.97895 | O4: =SQRT(SUM(frl!$G$2102:$G$2401)/300) -> 773.30038
A5: SPSA | B5: =fspsa!$H$2501 -> 789.02019 | C5: =B3/(LARGE(fspsa!$D$2:$D$2501,1)-SMALL(fspsa!$D$2:$D$2501,1)) -> 0.073225602 | D5: =SUM(fspsa!F2:F2501)/$B$14 -> 516.0508 | E5: =COUNTIF(fspsa!I2:I2501,1)/$B$14 -> 0.8892 | F5: =COUNTIF(fspsa!$J$2:$J$2501,1)/$B$14 -> 0.64 | H5: =SQRT(SUM(fspsa!$G$2:$G$301)/300) -> 713.5739 | I5: =SQRT(SUM(fspsa!$G$302:$G$601)/300) -> 768.77087 | J5: =SQRT(SUM(fspsa!$G$602:$G$901)/300) -> 750.38229 | K5: =SQRT(SUM(fspsa!$G$902:$G$1201)/300) -> 743.28503 | L5: =SQRT(SUM(fspsa!$G$1202:$G$1501)/300) -> 792.16463 | M5: =SQRT(SUM(fspsa!$G$1502:$G$1801)/300) -> 958.38181 | N5: =SQRT(SUM(fspsa!$G$1802:$G$2101)/300) -> 694.72839 | O5: =SQRT(SUM(fspsa!$G$2102:$G$2401)/300) -> 853.17512
A6: Bayes | B6: =fbayes!$H$2501 -> 790.73305 | C6: =B3/(LARGE(fbayes!$D$2:$D$2501,1)-SMALL(fbayes!$D$2:$D$2501,1)) -> 0.092359709 | D6: =SUM(fbayes!F2:F2501)/$B$14 -> 531.34 | E6: =COUNTIF(fbayes!I2:I2501,1)/$B$14 -> 0.8868 | F6: =COUNTIF(fbayes!$J$2:$J$2501,1)/$B$14 -> 0.6212 | H6: =SQRT(SUM(fbayes!$G$2:$G$301)/300) -> 769.41273 | I6: =SQRT(SUM(fbayes!$G$302:$G$601)/300) -> 731.57007 | J6: =SQRT(SUM(fbayes!$G$602:$G$901)/300) -> 756.40115 | K6: =SQRT(SUM(fbayes!$G$902:$G$1201)/300) -> 870.65512 | L6: =SQRT(SUM(fbayes!$G$1202:$G$1501)/300) -> 786.16153 | M6: =SQRT(SUM(fbayes!$G$1502:$G$1801)/300) -> 810.7321 | N6: =SQRT(SUM(fbayes!$G$1802:$G$2101)/300) -> 790.54151 | O6: =SQRT(SUM(fbayes!$G$2102:$G$2401)/300) -> 789.03939
A7: Evolution | B7: =fevol!$H$2501 -> 847.79783 | C7: =B3/(LARGE(fevol!$D$2:$D$2501,1)-SMALL(fevol!$D$2:$D$2501,1)) -> 0.076591876 | D7: =SUM(fevol!F2:F2501)/$B$14 -> 572.1928 | E7: =COUNTIF(fevol!I2:I2501,1)/$B$14 -> 0.8684 | F7: =COUNTIF(fevol!$J$2:$J$2501,1)/$B$14 -> 0.5876 | H7: =SQRT(SUM(fevol!$G$2:$G$301)/300) -> 792.66031 | I7: =SQRT(SUM(fevol!$G$302:$G$601)/300) -> 900.9707 | J7: =SQRT(SUM(fevol!$G$602:$G$901)/300) -> 782.56581 | K7: =SQRT(SUM(fevol!$G$902:$G$1201)/300) -> 855.2259 | L7: =SQRT(SUM(fevol!$G$1202:$G$1501)/300) -> 768.4249 | M7: =SQRT(SUM(fevol!$G$1502:$G$1801)/300) -> 1029.1334 | N7: =SQRT(SUM(fevol!$G$1802:$G$2101)/300) -> 806.7235 | O7: =SQRT(SUM(fevol!$G$2102:$G$2401)/300) -> 848.379
A8: PSO | B8: =fpso!$H$2501 -> 780.94103 | C8: =B3/(LARGE(fpso!$D$2:$D$2501,1)-SMALL(fpso!$D$2:$D$2501,1)) -> 0.10384848 | D8: =SUM(fpso!F2:F2501)/$B$14 -> 534.8716 | E8: =COUNTIF(fpso!I2:I2501,1)/$B$14 -> 0.8788 | F8: =COUNTIF(fpso!$J$2:$J$2501,1)/$B$14 -> 0.5968 | H8: =SQRT(SUM(fpso!$G$2:$G$301)/300) -> 811.67159 | I8: =SQRT(SUM(fpso!$G$302:$G$601)/300) -> 742.57843 | J8: =SQRT(SUM(fpso!$G$602:$G$901)/300) -> 823.25338 | K8: =SQRT(SUM(fpso!$G$902:$G$1201)/300) -> 772.90453 | L8: =SQRT(SUM(fpso!$G$1202:$G$1501)/300) -> 800.90651 | M8: =SQRT(SUM(fpso!$G$1502:$G$1801)/300) -> 725.96252 | N8: =SQRT(SUM(fpso!$G$1802:$G$2101)/300) -> 710.47568 | O8: =SQRT(SUM(fpso!$G$2102:$G$2401)/300) -> 840.13785
A9: Static | B9: =fstatic!$H$2501 -> 729.13249 | C9: =B3/(LARGE(fstatic!$D$2:$D$2501,1)-SMALL(fstatic!$D$2:$D$2501,1)) -> 0.1030266 | D9: =SUM(fstatic!F2:F2501)/$B$14 -> 502.722 | E9: =COUNTIF(fstatic!$I$2:$I$2501,1)/$B$14 -> 0.9096 | F9: =COUNTIF(fstatic!$J$2:$J$2501,1)/$B$14 -> 0.626 | H9: =SQRT(SUM(fstatic!$G$2:$G$301)/300) -> 747.23839 | I9: =SQRT(SUM(fstatic!$G$302:$G$601)/300) -> 718.26388 | J9: =SQRT(SUM(fstatic!$G$602:$G$901)/300) -> 721.1168 | K9: =SQRT(SUM(fstatic!$G$902:$G$1201)/300) -> 719.0398 | L9: =SQRT(SUM(fstatic!$G$1202:$G$1501)/300) -> 782.49173 | M9: =SQRT(SUM(fstatic!$G$1502:$G$1801)/300) -> 712.04831 | N9: =SQRT(SUM(fstatic!$G$1802:$G$2101)/300) -> 715.20865 | O9: =SQRT(SUM(fstatic!$G$2102:$G$2401)/300) -> 689.49484
A10: (*) Min-Max
H11: Optuna | I11: =voptuna!$G$301 -> 1073.3326 | J11: =voptuna!$G$601 -> 1049.758 | K11: =voptuna!$G$901 -> 1007.2047 | L11: =voptuna!$G$1201 -> 994.43972 | M11: =voptuna!$G$1501 -> 988.88314 | N11: =voptuna!$G$1801 -> 1002.3218 | O11: =voptuna!$G$2101 -> 1023.7026 | P11: =voptuna!$G$2401 -> 1029.9497
A12: Monitor Time (s) | B12: 1 | H12: RL | I12: =vrl!$G$301 -> 1078.1575 | J12: =vrl!$G$601 -> 1012.3436 | K12: =vrl!$G$901 -> 973.70234 | L12: =vrl!$G$1201 -> 970.33846 | M12: =vrl!$G$1501 -> 976.16907 | N12: =vrl!$G$1801 -> 985.51315 | O12: =vrl!$G$2101 -> 982.76268 | P12: =vrl!$G$2401 -> 990.3532
A13: Window Size | B13: 300 | H13: SPSA | I13: =vspsa!$G$301 -> 975.94892 | J13: =vspsa!$G$601 -> 1046.789 | K13: =vspsa!$G$901 -> 1057.9895 | L13: =vspsa!$G$1201 -> 1010.3984 | M13: =vspsa!$G$1501 -> 1178.5846 | N13: =vspsa!$G$1801 -> 1152.6229 | O13: =vspsa!$G$2101 -> 1142.255 | P13: =vspsa!$G$2401 -> 1131.9741
A14: Sample Size | B14: 2500 | H14: Bayes | I14: =vbayes!$G$301 -> 1137.6226 | J14: =vbayes!$G$601 -> 1136.6284 | K14: =vbayes!$G$901 -> 1100.0479 | L14: =vbayes!$G$1201 -> 1128.1189 | M14: =vbayes!$G$1501 -> 1174.7042 | N14: =vbayes!$G$1801 -> 1184.9422 | O14: =vbayes!$G$2101 -> 1193.1256 | P14: =vbayes!$G$2401 -> 1223.9877
A15: Same Level Setpoint | B15: 100 | H15: Evolution | I15: =voptuna!$G$301 -> 1073.3326 | J15: =voptuna!$G$601 -> 1049.758 | K15: =voptuna!$G$901 -> 1007.2047 | L15: =voptuna!$G$1201 -> 994.43972 | M15: =voptuna!$G$1501 -> 988.88314 | N15: =voptuna!$G$1801 -> 1002.3218 | O15: =voptuna!$G$2101 -> 1023.7026 | P15: =voptuna!$G$2401 -> 1029.9497
A16: Jitter | B16: On | H16: PSO | I16: =voptuna!$G$301 -> 1073.3326 | J16: =voptuna!$G$601 -> 1049.758 | K16: =voptuna!$G$901 -> 1007.2047 | L16: =voptuna!$G$1201 -> 994.43972 | M16: =voptuna!$G$1501 -> 988.88314 | N16: =voptuna!$G$1801 -> 1002.3218 | O16: =voptuna!$G$2101 -> 1023.7026 | P16: =voptuna!$G$2401 -> 1029.9497
H17: Static | I17: =voptuna!$G$301 -> 1073.3326 | J17: =voptuna!$G$601 -> 1049.758 | K17: =voptuna!$G$901 -> 1007.2047 | L17: =voptuna!$G$1201 -> 994.43972 | M17: =voptuna!$G$1501 -> 988.88314 | N17: =voptuna!$G$1801 -> 1002.3218 | O17: =voptuna!$G$2101 -> 1023.7026 | P17: =voptuna!$G$2401 -> 1029.9497

Sheet foptuna
A1: # | B1: PC | C1: Setpoint | D1: Rate | E1: Error | F1: Absolute error | G1: Error^2 | H1: RMSE | I1: Goal Range (20%) | J1: Goal Range (10%)
A2: 1 | B2: 1 | C2: 5000 | D2: 1417 | E2: =C2-D2 -> 3583 | F2: =ABS(E2) -> 3583 | G2: =POWER(E2,2) -> 12837889 | H2: =SQRT(SUM($G$2:G2)/A2) -> 3583 | I2: =IF(ABS(E2)/C2>0.2,0,1) -> 0 | J2: =IF(ABS(E2)/C2>0.1,0,1) -> 0
A3: 2 | B3: 5 | C3: 5000 | D3: 5128 | E3: =C3-D3 -> -128 | F3: =ABS(E3) -> 128 | G3: =POWER(E3,2) -> 16384 | H3: =SQRT(SUM($G$2:G3)/A3) -> 2535.1798 | I3: =IF(ABS(E3)/C3>0.2,0,1) -> 1 | J3: =IF(ABS(E3)/C3>0.1,0,1) -> 1
A4: 3 | B4: 3 | C4: 5000 | D4: 3327 | E4: =C4-D4 -> 1673 | F4: =ABS(E4) -> 1673 | G4: =POWER(E4,2) -> 2798929 | H4: =SQRT(SUM($G$2:G4)/A4) -> 2284.236 | I4: =IF(ABS(E4)/C4>0.2,0,1) -> 0 | J4: =IF(ABS(E4)/C4>0.1,0,1) -> 0
A5: 4 | B5: 6 | C5: 5000 | D5: 5740 | E5: =C5-D5 -> -740 | F5: =ABS(E5) -> 740 | G5: =POWER(E5,2) -> 547600 | H5: =SQRT(SUM($G$2:G5)/A5) -> 2012.511 | I5: =IF(ABS(E5)/C5>0.2,0,1) -> 1 | J5: =IF(ABS(E5)/C5>0.1,0,1) -> 0
A6: 5 | B6: 4 | C6: 5000 | D6: 4196 | E6: =C6-D6 -> 804 | F6: =ABS(E6) -> 804 | G6: =POWER(E6,2) -> 646416 | H6: =SQRT(SUM($G$2:G6)/A6) -> 1835.6044 | I6: =IF(ABS(E6)/C6>0.2,0,1) -> 1 | J6: =IF(ABS(E6)/C6>0.1,0,1) -> 0
A7: 6 | B7: 5 | C7: 5000 | D7: 4912 | E7: =C7-D7 -> 88 | F7: =ABS(E7) -> 88 | G7: =POWER(E7,2) -> 7744 | H7: =SQRT(SUM($G$2:G7)/A7) -> 1676.055 | I7: =IF(ABS(E7)/C7>0.2,0,1) -> 1 | J7: =IF(ABS(E7)/C7>0.1,0,1) -> 1
A8: 7 | B8: 5 | C8: 5000 | D8: 4125 | E8: =C8-D8 -> 875 | F8: =ABS(E8) -> 875 | G8: =POWER(E8,2) -> 765625 | H8: =SQRT(SUM($G$2:G8)/A8) -> 1586.577 | I8: =IF(ABS(E8)/C8>0.2,0,1) -> 1 | J8: =IF(ABS(E8)/C8>0.1,0,1) -> 0
A9: 8 | B9: 6 | C9: 5000 | D9: 4422 | E9: =C9-D9 -> 578 | F9: =ABS(E9) -> 578 | G9: =POWER(E9,2) -> 334084 | H9: =SQRT(SUM($G$2:G9)/A9) -> 1498.1101 | I9: =IF(ABS(E9)/C9>0.2,0,1) -> 1 | J9: =IF(ABS(E9)/C9>0.1,0,1) -> 0
A10: 9 | B10: 7 | C10: 5000 | D10: 5392 | E10: =C10-D10 -> -392 | F10: =ABS(E10) -> 392 | G10: =POWER(E10,2) -> 153664 | H10: =SQRT(SUM($G$2:G10)/A10) -> 1418.463 | I10: =IF(ABS(E10)/C10>0.2,0,1) -> 1 | J10: =IF(ABS(E10)/C10>0.1,0,1) -> 1
A11: 10 | B11: 6 | C11: 5000 | D11: 4908 | E11: =C11-D11 -> 92 | F11: =ABS(E11) -> 92 | G11: =POWER(E11,2) -> 8464 | H11: =SQRT(SUM($G$2:G11)/A11) -> 1345.9866 | I11: =IF(ABS(E11)/C11>0.2,0,1) -> 1 | J11: =IF(ABS(E11)/C11>0.1,0,1) -> 1
A12: 11 | B12: 6 | C12: 5000 | D12: 4276 | E12: =C12-D12 -> 724 | F12: =ABS(E12) -> 724 | G12: =POWER(E12,2) -> 524176 | H12: =SQRT(SUM($G$2:G12)/A12) -> 1301.7811 | I12: =IF(ABS(E12)/C12>0.2,0,1) -> 1 | J12: =IF(ABS(E12)/C12>0.1,0,1) -> 0
A13: 12 | B13: 7 | C13: 5000 | D13: 4825 | E13: =C13-D13 -> 175 | F13: =ABS(E13) -> 175 | G13: =POWER(E13,2) -> 30625 | H13: =SQRT(SUM($G$2:G13)/A13) -> 1247.3839 | I13: =IF(ABS(E13)/C13>0.2,0,1) -> 1 | J13: =IF(ABS(E13)/C13>0.1,0,1) -> 1
... A2501: 2500 | B2501: 9 | C2501: 5000 | D2501: 6277 | E2501: =C2501-D2501 -> -1277 | F2501: =ABS(E2501) -> 1277 | G2501: =POWER(E2501,2) -> 1630729 | H2501: =SQRT(SUM($G$2:G2501)/A2501) -> 768.06334 | I2501: =IF(ABS(E2501)/C2501>0.2,0,1) -> 0 | J2501: =IF(ABS(E2501)/C2501>0.1,0,1) -> 0

Sheet frl
A1: # | B1: PC | C1: Setpoint | D1: Rate | E1: Error | F1: Absolute error | G1: Error^2 | H1: RMSE | I1: Goal Range (20%) | J1: Goal Range (10%)
A2: 1 | B2: 1 | C2: 5000 | D2: 1759 | E2: =C2-D2 -> 3241 | F2: =ABS(E2) -> 3241 | G2: =POWER(E2,2) -> 10504081 | H2: =SQRT(SUM($G$2:G2)/A2) -> 3241 | I2: =IF(ABS(E2)/C2>0.2,0,1) -> 0 | J2: =IF(ABS(E2)/C2>0.1,0,1) -> 0
A3: 2 | B3: 4 | C3: 5000 | D3: 3043 | E3: =C3-D3 -> 1957 | F3: =ABS(E3) -> 1957 | G3: =POWER(E3,2) -> 3829849 | H3: =SQRT(SUM($G$2:G3)/A3) -> 2677.1188 | I3: =IF(ABS(E3)/C3>0.2,0,1) -> 0 | J3: =IF(ABS(E3)/C3>0.1,0,1) -> 0
A4: 3 | B4: 6 | C4: 5000 | D4: 5243 | E4: =C4-D4 -> -243 | F4: =ABS(E4) -> 243 | G4: =POWER(E4,2) -> 59049 | H4: =SQRT(SUM($G$2:G4)/A4) -> 2190.3561 | I4: =IF(ABS(E4)/C4>0.2,0,1) -> 1 | J4: =IF(ABS(E4)/C4>0.1,0,1) -> 1
A5: 4 | B5: 5 | C5: 5000 | D5: 4204 | E5: =C5-D5 -> 796 | F5: =ABS(E5) -> 796 | G5: =POWER(E5,2) -> 633616 | H5: =SQRT(SUM($G$2:G5)/A5) -> 1938.2076 | I5: =IF(ABS(E5)/C5>0.2,0,1) -> 1 | J5: =IF(ABS(E5)/C5>0.1,0,1) -> 0
A6: 5 | B6: 6 | C6: 5000 | D6: 4865 | E6: =C6-D6 -> 135 | F6: =ABS(E6) -> 135 | G6: =POWER(E6,2) -> 18225 | H6: =SQRT(SUM($G$2:G6)/A6) -> 1734.6366 | I6: =IF(ABS(E6)/C6>0.2,0,1) -> 1 | J6: =IF(ABS(E6)/C6>0.1,0,1) -> 1
A7: 6 | B7: 6 | C7: 5000 | D7: 4759 | E7: =C7-D7 -> 241 | F7: =ABS(E7) -> 241 | G7: =POWER(E7,2) -> 58081 | H7: =SQRT(SUM($G$2:G7)/A7) -> 1586.5529 | I7: =IF(ABS(E7)/C7>0.2,0,1) -> 1 | J7: =IF(ABS(E7)/C7>0.1,0,1) -> 1
A8: 7 | B8: 6 | C8: 5000 | D8: 4020 | E8: =C8-D8 -> 980 | F8: =ABS(E8) -> 980 | G8: =POWER(E8,2) -> 960400 | H8: =SQRT(SUM($G$2:G8)/A8) -> 1514.8456 | I8: =IF(ABS(E8)/C8>0.2,0,1) -> 1 | J8: =IF(ABS(E8)/C8>0.1,0,1) -> 0
A9: 8 | B9: 7 | C9: 5000 | D9: 3051 | E9: =C9-D9 -> 1949 | F9: =ABS(E9) -> 1949 | G9: =POWER(E9,2) -> 3798601 | H9: =SQRT(SUM($G$2:G9)/A9) -> 1575.6706 | I9: =IF(ABS(E9)/C9>0.2,0,1) -> 0 | J9: =IF(ABS(E9)/C9>0.1,0,1) -> 0
A10: 9 | B10: 9 | C10: 5000 | D10: 2445 | E10: =C10-D10 -> 2555 | F10: =ABS(E10) -> 2555 | G10: =POWER(E10,2) -> 6528025 | H10: =SQRT(SUM($G$2:G10)/A10) -> 1712.3709 | I10: =IF(ABS(E10)/C10>0.2,0,1) -> 0 | J10: =IF(ABS(E10)/C10>0.1,0,1) -> 0
A11: 10 | B11: 12 | C11: 5000 | D11: 5892 | E11: =C11-D11 -> -892 | F11: =ABS(E11) -> 892 | G11: =POWER(E11,2) -> 795664 | H11: =SQRT(SUM($G$2:G11)/A11) -> 1648.8054 | I11: =IF(ABS(E11)/C11>0.2,0,1) -> 1 | J11: =IF(ABS(E11)/C11>0.1,0,1) -> 0
A12: 11 | B12: 10 | C12: 5000 | D12: 5153 | E12: =C12-D12 -> -153 | F12: =ABS(E12) -> 153 | G12: =POWER(E12,2) -> 23409 | H12: =SQRT(SUM($G$2:G12)/A12) -> 1572.7509 | I12: =IF(ABS(E12)/C12>0.2,0,1) -> 1 | J12: =IF(ABS(E12)/C12>0.1,0,1) -> 1
A13: 12 | B13: 10 | C13: 5000 | D13: 6261 | E13: =C13-D13 -> -1261 | F13: =ABS(E13) -> 1261 | G13: =POWER(E13,2) -> 1590121 | H13: =SQRT(SUM($G$2:G13)/A13) -> 1549.1697 | I13: =IF(ABS(E13)/C13>0.2,0,1) -> 0 | J13: =IF(ABS(E13)/C13>0.1,0,1) -> 0
... A2501: 2500 | B2501: 7 | C2501: 5000 | D2501: 5296 | E2501: =C2501-D2501 -> -296 | F2501: =ABS(E2501) -> 296 | G2501: =POWER(E2501,2) -> 87616 | H2501: =SQRT(SUM($G$2:G2501)/A2501) -> 764.25004 | I2501: =IF(ABS(E2501)/C2501>0.2,0,1) -> 1 | J2501: =IF(ABS(E2501)/C2501>0.1,0,1) -> 1

Sheet fspsa
A1: # | B1: PC | C1: Setpoint | D1: Rate | E1: Error | F1: Absolute error | G1: Error^2 | H1: RMSE | I1: Goal Range (20%) | J1: Goal Range (10%)
A2: 1 | B2: 1 | C2: 5000 | D2: 1592 | E2: =C2-D2 -> 3408 | F2: =ABS(E2) -> 3408 | G2: =POWER(E2,2) -> 11614464 | H2: =SQRT(SUM($G$2:G2)/A2) -> 3408 | I2: =IF(ABS(E2)/C2>0.2,0,1) -> 0 | J2: =IF(ABS(E2)/C2>0.1,0,1) -> 0
A3: 2 | B3: 4 | C3: 5000 | D3: 3655 | E3: =C3-D3 -> 1345 | F3: =ABS(E3) -> 1345 | G3: =POWER(E3,2) -> 1809025 | H3: =SQRT(SUM($G$2:G3)/A3) -> 2590.7035 | I3: =IF(ABS(E3)/C3>0.2,0,1) -> 0 | J3: =IF(ABS(E3)/C3>0.1,0,1) -> 0
